Workbook
Name Impacto: Riesgos!$I$5:$I$10
Name Probabilidad: Riesgos!$G$5:$G$10

Sheet Definición
B2: Proyecto | C2: TRIPMATE
H3: Objetivos
B4: Subproyecto 1 | C4: TRIPMATE | I4: Identificar los objetivos específicos definidos para este subproyecto y que justifican su realización.
B6: Descripción | C6: Aplicación hibrida nativa para dispositivos moviles de Turismo que incluye las preferencias del usuario para mostrar el mejor plan de viaje.
H10: Objetivos
B11: Subproyecto 2 | C11: [Nombre ] | I11: Identificar los objetivos específicos definidos para este subproyecto y que justifican su realización.
B13: Descripción
H17: Objetivos
B18: Subproyecto 3 | C18: [Nombre ] | I18: Identificar los objetivos específicos definidos para este subproyecto y que justifican su realización.
B20: Descripción
H24: Objetivos
B25: Subproyecto 4 | C25: [Nombre ] | I25: Identificar los objetivos específicos definidos para este subproyecto y que justifican su realización.
B27: Descripción

Sheet Inversiones y Costes
A2: INVERSIONES / COSTES | D2: Subproyecto 1 | W2: Subproyecto 2 | AP2: Subproyecto 3 | BI2: Subproyecto 4 | CB2: PROYECTO GLOBAL
D4: TRIPMATE | W4: =+Definición!C11 -> [Nombre ] | AP4: =+Definición!C18 -> [Nombre ] | BI4: =+Definición!C25 -> [Nombre ] | CB4: =+Definición!C2 -> TRIPMATE
D6: Año 1 | G6: Año 2 | J6: Año 3 | M6: Año 4 | P6: Total | S6: Valor Residual | W6: Año 1 | Z6: Año 2 | AC6: Año 3 | AF6: Año 4 | AI6: Total | AL6: Valor Residual | AP6: Año 1 | AS6: Año 2 | AV6: Año 3 | AY6: Año 4 | BB6: Total | BE6: Valor Residual | BI6: Año 1 | BL6: Año 2 | BO6: Año 3 | BR6: Año 4 | BU6: Total | BX6: Valor Residual | CB6: Año 1 | CE6: Año 2 | CH6: Año 3 | CK6: Año 4 | CN6: Total | CQ6: Valor Residual
S7: (Fin año4) | AL7: (Fin año4) | BE7: (Fin año4) | BX7: (Fin año4) | CQ7: (Fin año4)
A9: TOTAL INVERS. y COSTES | D9: =SUM(D11:D79)/2 -> 1593000 | G9: =SUM(G11:G79)/2 -> 227000 | J9: =SUM(J11:J79)/2 -> 311000 | M9: =SUM(M11:M79)/2 -> 157000 | P9: =SUM(P11:P79)/2 -> 2288000 | S9: =SUM(S11:S79)/2 -> 0 | W9: =SUM(W11:W79)/2 -> 0 | Z9: =SUM(Z11:Z79)/2 -> 0 | AC9: =SUM(AC11:AC79)/2 -> 0 | AF9: =SUM(AF11:AF79)/2 -> 0 | AI9: =SUM(AI11:AI79)/2 -> 0 | AL9: =SUM(AL11:AL79)/2 -> 0 | AP9: =SUM(AP11:AP79)/2 -> 0 | AS9: =SUM(AS11:AS79)/2 -> 0 | AV9: =SUM(AV11:AV79)/2 -> 0 | AY9: =SUM(AY11:AY79)/2 -> 0 | BB9: =SUM(BB11:BB79)/2 -> 0 | BE9: =SUM(BE11:BE79)/2 -> 0 | BI9: =SUM(BI11:BI79)/2 -> 0 | BL9: =SUM(BL11:BL79)/2 -> 0 | BO9: =SUM(BO11:BO79)/2 -> 0 | BR9: =SUM(BR11:BR79)/2 -> 0 | BU9: =SUM(BU11:BU79)/2 -> 0 | BX9: =SUM(BX11:BX79)/2 -> 0 | CB9: =SUM(CB11:CB79)/2 -> 1593000 | CE9: =SUM(CE11:CE79)/2 -> 227000 | CH9: =SUM(CH11:CH79)/2 -> 311000 | CK9: =SUM(CK11:CK79)/2 -> 157000 | CN9: =SUM(CN11:CN79)/2 -> 2288000 | CQ9: =SUM(CQ11:CQ79)/2 -> 0
A12: Inmovilizado y equipos | D12: =SUM(D14:D33) -> 20000 | G12: =SUM(G14:G33) -> 7000 | J12: =SUM(J14:J33) -> 7000 | M12: =SUM(M14:M33) -> 7000 | P12: =SUM(P14:P33) -> 41000 | S12: =SUM(S14:S33) -> 0 | W12: =SUM(W14:W33) -> 0 | Z12: =SUM(Z14:Z33) -> 0 | AC12: =SUM(AC14:AC33) -> 0 | AF12: =SUM(AF14:AF33) -> 0 | AI12: =SUM(AI14:AI33) -> 0 | AL12: =SUM(AL14:AL33) -> 0 | AP12: =SUM(AP14:AP33) -> 0 | AS12: =SUM(AS14:AS33) -> 0 | AV12: =SUM(AV14:AV33) -> 0 | AY12: =SUM(AY14:AY33) -> 0 | BB12: =SUM(BB14:BB33) -> 0 | BE12: =SUM(BE14:BE33) -> 0 | BI12: =SUM(BI14:BI33) -> 0 | BL12: =SUM(BL14:BL33) -> 0 | BO12: =SUM(BO14:BO33) -> 0 | BR12: =SUM(BR14:BR33) -> 0 | BU12: =SUM(BU14:BU33) -> 0 | BX12: =SUM(BX14:BX33) -> 0 | CB12: =SUM(CB14:CB33) -> 20000 | CE12: =SUM(CE14:CE33) -> 7000 | CH12: =SUM(CH14:CH33) -> 7000 | CK12: =SUM(CK14:CK33) -> 7000 | CN12: =SUM(CN14:CN33) -> 41000 | CQ12: =SUM(CQ14:CQ33) -> 0
A14: HARDWARE | D14: 20000 | G14: 7000 | J14: 7000 | M14: 7000 | P14: =SUM(D14:M14) -> 41000 | W14: 0 | Z14: 0 | AC14: 0 | AF14: 0 | AI14: =SUM(W14:AF14) -> 0 | AP14: 0 | AS14: 0 | AV14: 0 | AY14: 0 | BB14: =SUM(AP14:AY14) -> 0 | BI14: 0 | BL14: 0 | BO14: 0 | BR14: 0 | BU14: =SUM(BI14:BR14) -> 0 | CB14: =+D14+W14+AP14+BI14 -> 20000 | CE14: =+G14+Z14+AS14+BL14 -> 7000 | CH14: =+J14+AC14+AV14+BO14 -> 7000 | CK14: =+M14+AF14+AY14+BR14 -> 7000 | CN14: =SUM(CB14:CK14) -> 41000 | CQ14: =+S14+AL14+BE14+BX14 -> 0
D16: 0 | G16: 0 | J16: 0 | M16: 0 | P16: =SUM(D16:M16) -> 0 | W16: 0 | Z16: 0 | AC16: 0 | AF16: 0 | AI16: =SUM(W16:AF16) -> 0 | AP16: 0 | AS16: 0 | AV16: 0 | AY16: 0 | BB16: =SUM(AP16:AY16) -> 0 | BI16: 0 | BL16: 0 | BO16: 0 | BR16: 0 | BU16: =SUM(BI16:BR16) -> 0 | CB16: =+D16+W16+AP16+BI16 -> 0 | CE16: =+G16+Z16+AS16+BL16 -> 0 | CH16: =+J16+AC16+AV16+BO16 -> 0 | CK16: =+M16+AF16+AY16+BR16 -> 0 | CN16: =SUM(CB16:CK16) -> 0 | CQ16: =+S16+AL16+BE16+BX16 -> 0
D18: 0 | G18: 0 | J18: 0 | M18: 0 | P18: =SUM(D18:M18) -> 0 | W18: 0 | Z18: 0 | AC18: 0 | AF18: 0 | AI18: =SUM(W18:AF18) -> 0 | AP18: 0 | AS18: 0 | AV18: 0 | AY18: 0 | BB18: =SUM(AP18:AY18) -> 0 | BI18: 0 | BL18: 0 | BO18: 0 | BR18: 0 | BU18: =SUM(BI18:BR18) -> 0 | CB18: =+D18+W18+AP18+BI18 -> 0 | CE18: =+G18+Z18+AS18+BL18 -> 0 | CH18: =+J18+AC18+AV18+BO18 -> 0 | CK18: =+M18+AF18+AY18+BR18 -> 0 | CN18: =SUM(CB18:CK18) -> 0 | CQ18: =+S18+AL18+BE18+BX18 -> 0
D20: 0 | G20: 0 | J20: 0 | M20: 0 | P20: =SUM(D20:M20) -> 0 | W20: 0 | Z20: 0 | AC20: 0 | AF20: 0 | AI20: =SUM(W20:AF20) -> 0 | AP20: 0 | AS20: 0 | AV20: 0 | AY20: 0 | BB20: =SUM(AP20:AY20) -> 0 | BI20: 0 | BL20: 0 | BO20: 0 | BR20: 0 | BU20: =SUM(BI20:BR20) -> 0 | CB20: =+D20+W20+AP20+BI20 -> 0 | CE20: =+G20+Z20+AS20+BL20 -> 0 | CH20: =+J20+AC20+AV20+BO20 -> 0 | CK20: =+M20+AF20+AY20+BR20 -> 0 | CN20: =SUM(CB20:CK20) -> 0 | CQ20: =+S20+AL20+BE20+BX20 -> 0
D22: 0 | G22: 0 | J22: 0 | M22: 0 | P22: =SUM(D22:M22) -> 0 | W22: 0 | Z22: 0 | AC22: 0 | AF22: 0 | AI22: =SUM(W22:AF22) -> 0 | AP22: 0 | AS22: 0 | AV22: 0 | AY22: 0 | BB22: =SUM(AP22:AY22) -> 0 | BI22: 0 | BL22: 0 | BO22: 0 | BR22: 0 | BU22: =SUM(BI22:BR22) -> 0 | CB22: =+D22+W22+AP22+BI22 -> 0 | CE22: =+G22+Z22+AS22+BL22 -> 0 | CH22: =+J22+AC22+AV22+BO22 -> 0 | CK22: =+M22+AF22+AY22+BR22 -> 0 | CN22: =SUM(CB22:CK22) -> 0 | CQ22: =+S22+AL22+BE22+BX22 -> 0
D24: 0 | G24: 0 | J24: 0 | M24: 0 | P24: =SUM(D24:M24) -> 0 | W24: 0 | Z24: 0 | AC24: 0 | AF24: 0 | AI24: =SUM(W24:AF24) -> 0 | AP24: 0 | AS24: 0 | AV24: 0 | AY24: 0 | BB24: =SUM(AP24:AY24) -> 0 | BI24: 0 | BL24: 0 | BO24: 0 | BR24: 0 | BU24: =SUM(BI24:BR24) -> 0 | CB24: =+D24+W24+AP24+BI24 -> 0 | CE24: =+G24+Z24+AS24+BL24 -> 0 | CH24: =+J24+AC24+AV24+BO24 -> 0 | CK24: =+M24+AF24+AY24+BR24 -> 0 | CN24: =SUM(CB24:CK24) -> 0 | CQ24: =+S24+AL24+BE24+BX24 -> 0
D26: 0 | G26: 0 | J26: 0 | M26: 0 | P26: =SUM(D26:M26) -> 0 | W26: 0 | Z26: 0 | AC26: 0 | AF26: 0 | AI26: =SUM(W26:AF26) -> 0 | AP26: 0 | AS26: 0 | AV26: 0 | AY26: 0 | BB26: =SUM(AP26:AY26) -> 0 | BI26: 0 | BL26: 0 | BO26: 0 | BR26: 0 | BU26: =SUM(BI26:BR26) -> 0 | CB26: =+D26+W26+AP26+BI26 -> 0 | CE26: =+G26+Z26+AS26+BL26 -> 0 | CH26: =+J26+AC26+AV26+BO26 -> 0 | CK26: =+M26+AF26+AY26+BR26 -> 0 | CN26: =SUM(CB26:CK26) -> 0 | CQ26: =+S26+AL26+BE26+BX26 -> 0
D28: 0 | G28: 0 | J28: 0 | M28: 0 | P28: =SUM(D28:M28) -> 0 | W28: 0 | Z28: 0 | AC28: 0 | AF28: 0 | AI28: =SUM(W28:AF28) -> 0 | AP28: 0 | AS28: 0 | AV28: 0 | AY28: 0 | BB28: =SUM(AP28:AY28) -> 0 | BI28: 0 | BL28: 0 | BO28: 0 | BR28: 0 | BU28: =SUM(BI28:BR28) -> 0 | CB28: =+D28+W28+AP28+BI28 -> 0 | CE28: =+G28+Z28+AS28+BL28 -> 0 | CH28: =+J28+AC28+AV28+BO28 -> 0 | CK28: =+M28+AF28+AY28+BR28 -> 0 | CN28: =SUM(CB28:CK28) -> 0 | CQ28: =+S28+AL28+BE28+BX28 -> 0
D30: 0 | G30: 0 | J30: 0 | M30: 0 | P30: =SUM(D30:M30) -> 0 | W30: 0 | Z30: 0 | AC30: 0 | AF30: 0 | AI30: =SUM(W30:AF30) -> 0 | AP30: 0 | AS30: 0 | AV30: 0 | AY30: 0 | BB30: =SUM(AP30:AY30) -> 0 | BI30: 0 | BL30: 0 | BO30: 0 | BR30: 0 | BU30: =SUM(BI30:BR30) -> 0 | CB30: =+D30+W30+AP30+BI30 -> 0 | CE30: =+G30+Z30+AS30+BL30 -> 0 | CH30: =+J30+AC30+AV30+BO30 -> 0 | CK30: =+M30+AF30+AY30+BR30 -> 0 | CN30: =SUM(CB30:CK30) -> 0 | CQ30: =+S30+AL30+BE30+BX30 -> 0
D32: 0 | G32: 0 | J32: 0 | M32: 0 | P32: =SUM(D32:M32) -> 0 | W32: 0 | Z32: 0 | AC32: 0 | AF32: 0 | AI32: =SUM(W32:AF32) -> 0 | AP32: 0 | AS32: 0 | AV32: 0 | AY32: 0 | BB32: =SUM(AP32:AY32) -> 0 | BI32: 0 | BL32: 0 | BO32: 0 | BR32: 0 | BU32: =SUM(BI32:BR32) -> 0 | CB32: =+D32+W32+AP32+BI32 -> 0 | CE32: =+G32+Z32+AS32+BL32 -> 0 | CH32: =+J32+AC32+AV32+BO32 -> 0 | CK32: =+M32+AF32+AY32+BR32 -> 0 | CN32: =SUM(CB32:CK32) -> 0 | CQ32: =+S32+AL32+BE32+BX32 -> 0
A35: Licencias SW y SW Base | D35: =SUM(D37:D56) -> 1408000 | G35: =SUM(G37:G56) -> 70000 | J35: =SUM(J37:J56) -> 154000 | M35: =SUM(M37:M56) -> 0 | P35: =SUM(P37:P56) -> 1632000 | S35: =SUM(S37:S56) -> 0 | W35: =SUM(W37:W56) -> 0 | Z35: =SUM(Z37:Z56) -> 0 | AC35: =SUM(AC37:AC56) -> 0 | AF35: =SUM(AF37:AF56) -> 0 | AI35: =SUM(AI37:AI56) -> 0 | AL35: =SUM(AL37:AL56) -> 0 | AP35: =SUM(AP37:AP56) -> 0 | AS35: =SUM(AS37:AS56) -> 0 | AV35: =SUM(AV37:AV56) -> 0 | AY35: =SUM(AY37:AY56) -> 0 | BB35: =SUM(BB37:BB56) -> 0 | BE35: =SUM(BE37:BE56) -> 0 | BI35: =SUM(BI37:BI56) -> 0 | BL35: =SUM(BL37:BL56) -> 0 | BO35: =SUM(BO37:BO56) -> 0 | BR35: =SUM(BR37:BR56) -> 0 | BU35: =SUM(BU37:BU56) -> 0 | BX35: =SUM(BX37:BX56) -> 0 | CB35: =SUM(CB37:CB56) -> 1408000 | CE35: =SUM(CE37:CE56) -> 70000 | CH35: =SUM(CH37:CH56) -> 154000 | CK35: =SUM(CK37:CK56) -> 0 | CN35: =SUM(CN37:CN56) -> 1632000 | CQ35: =SUM(CQ37:CQ56) -> 0
A37: DB2 | D37: 48000 | G37: 0 | J37: 24000 | M37: 0 | P37: =SUM(D37:M37) -> 72000 | W37: 0 | Z37: 0 | AC37: 0 | AF37: 0 | AI37: =SUM(W37:AF37) -> 0 | AP37: 0 | AS37: 0 | AV37: 0 | AY37: 0 | BB37: =SUM(AP37:AY37) -> 0 | BI37: 0 | BL37: 0 | BO37: 0 | BR37: 0 | BU37: =SUM(BI37:BR37) -> 0 | CB37: =+D37+W37+AP37+BI37 -> 48000 | CE37: =+G37+Z37+AS37+BL37 -> 0 | CH37: =+J37+AC37+AV37+BO37 -> 24000 | CK37: =+M37+AF37+AY37+BR37 -> 0 | CN37: =SUM(CB37:CK37) -> 72000 | CQ37: =+S37+AL37+BE37+BX37 -> 0
A39: IMB WORKLIGHT | D39: 60000 | G39: 0 | J39: 60000 | M39: 0 | P39: =SUM(D39:M39) -> 120000 | W39: 0 | Z39: 0 | AC39: 0 | AF39: 0 | AI39: =SUM(W39:AF39) -> 0 | AP39: 0 | AS39: 0 | AV39: 0 | AY39: 0 | BB39: =SUM(AP39:AY39) -> 0 | BI39: 0 | BL39: 0 | BO39: 0 | BR39: 0 | BU39: =SUM(BI39:BR39) -> 0 | CB39: =+D39+W39+AP39+BI39 -> 60000 | CE39: =+G39+Z39+AS39+BL39 -> 0 | CH39: =+J39+AC39+AV39+BO39 -> 60000 | CK39: =+M39+AF39+AY39+BR39 -> 0 | CN39: =SUM(CB39:CK39) -> 120000 | CQ39: =+S39+AL39+BE39+BX39 -> 0
A41: GIS | D41: 500000 | G41: 50000 | J41: 50000 | M41: 0 | P41: =SUM(D41:M41) -> 600000 | W41: 0 | Z41: 0 | AC41: 0 | AF41: 0 | AI41: =SUM(W41:AF41) -> 0 | AP41: 0 | AS41: 0 | AV41: 0 | AY41: 0 | BB41: =SUM(AP41:AY41) -> 0 | BI41: 0 | BL41: 0 | BO41: 0 | BR41: 0 | BU41: =SUM(BI41:BR41) -> 0 | CB41: =+D41+W41+AP41+BI41 -> 500000 | CE41: =+G41+Z41+AS41+BL41 -> 50000 | CH41: =+J41+AC41+AV41+BO41 -> 50000 | CK41: =+M41+AF41+AY41+BR41 -> 0 | CN41: =SUM(CB41:CK41) -> 600000 | CQ41: =+S41+AL41+BE41+BX41 -> 0
A43: SOFTWARE NAVEGACION | D43: 500000 | G43: 20000 | J43: 20000 | M43: 0 | P43: =SUM(D43:M43) -> 540000 | W43: 0 | Z43: 0 | AC43: 0 | AF43: 0 | AI43: =SUM(W43:AF43) -> 0 | AP43: 0 | AS43: 0 | AV43: 0 | AY43: 0 | BB43: =SUM(AP43:AY43) -> 0 | BI43: 0 | BL43: 0 | BO43: 0 | BR43: 0 | BU43: =SUM(BI43:BR43) -> 0 | CB43: =+D43+W43+AP43+BI43 -> 500000 | CE43: =+G43+Z43+AS43+BL43 -> 20000 | CH43: =+J43+AC43+AV43+BO43 -> 20000 | CK43: =+M43+AF43+AY43+BR43 -> 0 | CN43: =SUM(CB43:CK43) -> 540000 | CQ43: =+S43+AL43+BE43+BX43 -> 0
A45: PILOTO | D45: 300000 | G45: 0 | J45: 0 | M45: 0 | P45: =SUM(D45:M45) -> 300000 | W45: 0 | Z45: 0 | AC45: 0 | AF45: 0 | AI45: =SUM(W45:AF45) -> 0 | AP45: 0 | AS45: 0 | AV45: 0 | AY45: 0 | BB45: =SUM(AP45:AY45) -> 0 | BI45: 0 | BL45: 0 | BO45: 0 | BR45: 0 | BU45: =SUM(BI45:BR45) -> 0 | CB45: =+D45+W45+AP45+BI45 -> 300000 | CE45: =+G45+Z45+AS45+BL45 -> 0 | CH45: =+J45+AC45+AV45+BO45 -> 0 | CK45: =+M45+AF45+AY45+BR45 -> 0 | CN45: =SUM(CB45:CK45) -> 300000 | CQ45: =+S45+AL45+BE45+BX45 -> 0
D47: 0 | G47: 0 | J47: 0 | M47: 0 | P47: =SUM(D47:M47) -> 0 | W47: 0 | Z47: 0 | AC47: 0 | AF47: 0 | AI47: =SUM(W47:AF47) -> 0 | AP47: 0 | AS47: 0 | AV47: 0 | AY47: 0 | BB47: =SUM(AP47:AY47) -> 0 | BI47: 0 | BL47: 0 | BO47: 0 | BR47: 0 | BU47: =SUM(BI47:BR47) -> 0 | CB47: =+D47+W47+AP47+BI47 -> 0 | CE47: =+G47+Z47+AS47+BL47 -> 0 | CH47: =+J47+AC47+AV47+BO47 -> 0 | CK47: =+M47+AF47+AY47+BR47 -> 0 | CN47: =SUM(CB47:CK47) -> 0 | CQ47: =+S47+AL47+BE47+BX47 -> 0
D49: 0 | G49: 0 | J49: 0 | M49: 0 | P49: =SUM(D49:M49) -> 0 | W49: 0 | Z49: 0 | AC49: 0 | AF49: 0 | AI49: =SUM(W49:AF49) -> 0 | AP49: 0 | AS49: 0 | AV49: 0 | AY49: 0 | BB49: =SUM(AP49:AY49) -> 0 | BI49: 0 | BL49: 0 | BO49: 0 | BR49: 0 | BU49: =SUM(BI49:BR49) -> 0 | CB49: =+D49+W49+AP49+BI49 -> 0 | CE49: =+G49+Z49+AS49+BL49 -> 0 | CH49: =+J49+AC49+AV49+BO49 -> 0 | CK49: =+M49+AF49+AY49+BR49 -> 0 | CN49: =SUM(CB49:CK49) -> 0 | CQ49: =+S49+AL49+BE49+BX49 -> 0
D51: 0 | G51: 0 | J51: 0 | M51: 0 | P51: =SUM(D51:M51) -> 0 | W51: 0 | Z51: 0 | AC51: 0 | AF51: 0 | AI51: =SUM(W51:AF51) -> 0 | AP51: 0 | AS51: 0 | AV51: 0 | AY51: 0 | BB51: =SUM(AP51:AY51) -> 0 | BI51: 0 | BL51: 0 | BO51: 0 | BR51: 0 | BU51: =SUM(BI51:BR51) -> 0 | CB51: =+D51+W51+AP51+BI51 -> 0 | CE51: =+G51+Z51+AS51+BL51 -> 0 | CH51: =+J51+AC51+AV51+BO51 -> 0 | CK51: =+M51+AF51+AY51+BR51 -> 0 | CN51: =SUM(CB51:CK51) -> 0 | CQ51: =+S51+AL51+BE51+BX51 -> 0
D53: 0 | G53: 0 | J53: 0 | M53: 0 | P53: =SUM(D53:M53) -> 0 | W53: 0 | Z53: 0 | AC53: 0 | AF53: 0 | AI53: =SUM(W53:AF53) -> 0 | AP53: 0 | AS53: 0 | AV53: 0 | AY53: 0 | BB53: =SUM(AP53:AY53) -> 0 | BI53: 0 | BL53: 0 | BO53: 0 | BR53: 0 | BU53: =SUM(BI53:BR53) -> 0 | CB53: =+D53+W53+AP53+BI53 -> 0 | CE53: =+G53+Z53+AS53+BL53 -> 0 | CH53: =+J53+AC53+AV53+BO53 -> 0 | CK53: =+M53+AF53+AY53+BR53 -> 0 | CN53: =SUM(CB53:CK53) -> 0 | CQ53: =+S53+AL53+BE53+BX53 -> 0
D55: 0 | G55: 0 | J55: 0 | M55: 0 | P55: =SUM(D55:M55) -> 0 | W55: 0 | Z55: 0 | AC55: 0 | AF55: 0 | AI55: =SUM(W55:AF55) -> 0 | AP55: 0 | AS55: 0 | AV55: 0 | AY55: 0 | BB55: =SUM(AP55:AY55) -> 0 | BI55: 0 | BL55: 0 | BO55: 0 | BR55: 0 | BU55: =SUM(BI55:BR55) -> 0 | CB55: =+D55+W55+AP55+BI55 -> 0 | CE55: =+G55+Z55+AS55+BL55 -> 0 | CH55: =+J55+AC55+AV55+BO55 -> 0 | CK55: =+M55+AF55+AY55+BR55 -> 0 | CN55: =SUM(CB55:CK55) -> 0 | CQ55: =+S55+AL55+BE55+BX55 -> 0
A58: Servicios Externos | D58: =SUM(D60:D79) -> 165000 | G58: =SUM(G60:G79) -> 150000 | J58: =SUM(J60:J79) -> 150000 | M58: =SUM(M60:M79) -> 150000 | P58: =SUM(P60:P79) -> 615000 | S58: =SUM(S60:S79) -> 0 | W58: =SUM(W60:W79) -> 0 | Z58: =SUM(Z60:Z79) -> 0 | AC58: =SUM(AC60:AC79) -> 0 | AF58: =SUM(AF60:AF79) -> 0 | AI58: =SUM(AI60:AI79) -> 0 | AL58: =SUM(AL60:AL79) -> 0 | AP58: =SUM(AP60:AP79) -> 0 | AS58: =SUM(AS60:AS79) -> 0 | AV58: =SUM(AV60:AV79) -> 0 | AY58: =SUM(AY60:AY79) -> 0 | BB58: =SUM(BB60:BB79) -> 0 | BE58: =SUM(BE60:BE79) -> 0 | BI58: =SUM(BI60:BI79) -> 0 | BL58: =SUM(BL60:BL79) -> 0 | BO58: =SUM(BO60:BO79) -> 0 | BR58: =SUM(BR60:BR79) -> 0 | BU58: =SUM(BU60:BU79) -> 0 | BX58: =SUM(BX60:BX79) -> 0 | CB58: =SUM(CB60:CB79) -> 165000 | CE58: =SUM(CE60:CE79) -> 150000 | CH58: =SUM(CH60:CH79) -> 150000 | CK58: =SUM(CK60:CK79) -> 150000 | CN58: =SUM(CN60:CN79) -> 615000 | CQ58: =SUM(CQ60:CQ79) -> 0
D60: 0 | G60: 0 | J60: 0 | M60: 0 | P60: =SUM(D60:M60) -> 0 | W60: 0 | Z60: 0 | AC60: 0 | AF60: 0 | AI60: =SUM(W60:AF60) -> 0 | AP60: 0 | AS60: 0 | AV60: 0 | AY60: 0 | BB60: =SUM(AP60:AY60) -> 0 | BI60: 0 | BL60: 0 | BO60: 0 | BR60: 0 | BU60: =SUM(BI60:BR60) -> 0 | CB60: =+D60+W60+AP60+BI60 -> 0 | CE60: =+G60+Z60+AS60+BL60 -> 0 | CH60: =+J60+AC60+AV60+BO60 -> 0 | CK60: =+M60+AF60+AY60+BR60 -> 0 | CN60: =SUM(CB60:CK60) -> 0 | CQ60: =+S60+AL60+BE60+BX60 -> 0
D62: 0 | G62: 0 | J62: 0 | M62: 0 | P62: =SUM(D62:M62) -> 0 | W62: 0 | Z62: 0 | AC62: 0 | AF62: 0 | AI62: =SUM(W62:AF62) -> 0 | AP62: 0 | AS62: 0 | AV62: 0 | AY62: 0 | BB62: =SUM(AP62:AY62) -> 0 | BI62: 0 | BL62: 0 | BO62: 0 | BR62: 0 | BU62: =SUM(BI62:BR62) -> 0 | CB62: =+D62+W62+AP62+BI62 -> 0 | CE62: =+G62+Z62+AS62+BL62 -> 0 | CH62: =+J62+AC62+AV62+BO62 -> 0 | CK62: =+M62+AF62+AY62+BR62 -> 0 | CN62: =SUM(CB62:CK62) -> 0 | CQ62: =+S62+AL62+BE62+BX62 -> 0
A64: PATENTES Y MARCAS | D64: 15000 | G64: 0 | J64: 0 | M64: 0 | P64: =SUM(D64:M64) -> 15000 | W64: 0 | Z64: 0 | AC64: 0 | AF64: 0 | AI64: =SUM(W64:AF64) -> 0 | AP64: 0 | AS64: 0 | AV64: 0 | AY64: 0 | BB64: =SUM(AP64:AY64) -> 0 | BI64: 0 | BL64: 0 | BO64: 0 | BR64: 0 | BU64: =SUM(BI64:BR64) -> 0 | CB64: =+D64+W64+AP64+BI64 -> 15000 | CE64: =+G64+Z64+AS64+BL64 -> 0 | CH64: =+J64+AC64+AV64+BO64 -> 0 | CK64: =+M64+AF64+AY64+BR64 -> 0 | CN64: =SUM(CB64:CK64) -> 15000 | CQ64: =+S64+AL64+BE64+BX64 -> 0
A66: MANTENIMIIENTO Y LEASING | D66: 150000 | G66: 150000 | J66: 150000 | M66: 150000 | P66: =SUM(D66:M66) -> 600000 | W66: 0 | Z66: 0 | AC66: 0 | AF66: 0 | AI66: =SUM(W66:AF66) -> 0 | AP66: 0 | AS66: 0 | AV66: 0 | AY66: 0 | BB66: =SUM(AP66:AY66) -> 0 | BI66: 0 | BL66: 0 | BO66: 0 | BR66: 0 | BU66: =SUM(BI66:BR66) -> 0 | CB66: =+D66+W66+AP66+BI66 -> 150000 | CE66: =+G66+Z66+AS66+BL66 -> 150000 | CH66: =+J66+AC66+AV66+BO66 -> 150000 | CK66: =+M66+AF66+AY66+BR66 -> 150000 | CN66: =SUM(CB66:CK66) -> 600000 | CQ66: =+S66+AL66+BE66+BX66 -> 0
D68: 0 | G68: 0 | J68: 0 | M68: 0 | P68: =SUM(D68:M68) -> 0 | W68: 0 | Z68: 0 | AC68: 0 | AF68: 0 | AI68: =SUM(W68:AF68) -> 0 | AP68: 0 | AS68: 0 | AV68: 0 | AY68: 0 | BB68: =SUM(AP68:AY68) -> 0 | BI68: 0 | BL68: 0 | BO68: 0 | BR68: 0 | BU68: =SUM(BI68:BR68) -> 0 | CB68: =+D68+W68+AP68+BI68 -> 0 | CE68: =+G68+Z68+AS68+BL68 -> 0 | CH68: =+J68+AC68+AV68+BO68 -> 0 | CK68: =+M68+AF68+AY68+BR68 -> 0 | CN68: =SUM(CB68:CK68) -> 0 | CQ68: =+S68+AL68+BE68+BX68 -> 0
D70: 0 | G70: 0 | J70: 0 | M70: 0 | P70: =SUM(D70:M70) -> 0 | W70: 0 | Z70: 0 | AC70: 0 | AF70: 0 | AI70: =SUM(W70:AF70) -> 0 | AP70: 0 | AS70: 0 | AV70: 0 | AY70: 0 | BB70: =SUM(AP70:AY70) -> 0 | BI70: 0 | BL70: 0 | BO70: 0 | BR70: 0 | BU70: =SUM(BI70:BR70) -> 0 | CB70: =+D70+W70+AP70+BI70 -> 0 | CE70: =+G70+Z70+AS70+BL70 -> 0 | CH70: =+J70+AC70+AV70+BO70 -> 0 | CK70: =+M70+AF70+AY70+BR70 -> 0 | CN70: =SUM(CB70:CK70) -> 0 | CQ70: =+S70+AL70+BE70+BX70 -> 0
D72: 0 | G72: 0 | J72: 0 | M72: 0 | P72: =SUM(D72:M72) -> 0 | W72: 0 | Z72: 0 | AC72: 0 | AF72: 0 | AI72: =SUM(W72:AF72) -> 0 | AP72: 0 | AS72: 0 | AV72: 0 | AY72: 0 | BB72: =SUM(AP72:AY72) -> 0 | BI72: 0 | BL72: 0 | BO72: 0 | BR72: 0 | BU72: =SUM(BI72:BR72) -> 0 | CB72: =+D72+W72+AP72+BI72 -> 0 | CE72: =+G72+Z72+AS72+BL72 -> 0 | CH72: =+J72+AC72+AV72+BO72 -> 0 | CK72: =+M72+AF72+AY72+BR72 -> 0 | CN72: =SUM(CB72:CK72) -> 0 | CQ72: =+S72+AL72+BE72+BX72 -> 0
D74: 0 | G74: 0 | J74: 0 | M74: 0 | P74: =SUM(D74:M74) -> 0 | W74: 0 | Z74: 0 | AC74: 0 | AF74: 0 | AI74: =SUM(W74:AF74) -> 0 | AP74: 0 | AS74: 0 | AV74: 0 | AY74: 0 | BB74: =SUM(AP74:AY74) -> 0 | BI74: 0 | BL74: 0 | BO74: 0 | BR74: 0 | BU74: =SUM(BI74:BR74) -> 0 | CB74: =+D74+W74+AP74+BI74 -> 0 | CE74: =+G74+Z74+AS74+BL74 -> 0 | CH74: =+J74+AC74+AV74+BO74 -> 0 | CK74: =+M74+AF74+AY74+BR74 -> 0 | CN74: =SUM(CB74:CK74) -> 0 | CQ74: =+S74+AL74+BE74+BX74 -> 0
D76: 0 | G76: 0 | J76: 0 | M76: 0 | P76: =SUM(D76:M76) -> 0 | W76: 0 | Z76: 0 | AC76: 0 | AF76: 0 | AI76: =SUM(W76:AF76) -> 0 | AP76: 0 | AS76: 0 | AV76: 0 | AY76: 0 | BB76: =SUM(AP76:AY76) -> 0 | BI76: 0 | BL76: 0 | BO76: 0 | BR76: 0 | BU76: =SUM(BI76:BR76) -> 0 | CB76: =+D76+W76+AP76+BI76 -> 0 | CE76: =+G76+Z76+AS76+BL76 -> 0 | CH76: =+J76+AC76+AV76+BO76 -> 0 | CK76: =+M76+AF76+AY76+BR76 -> 0 | CN76: =SUM(CB76:CK76) -> 0 | CQ76: =+S76+AL76+BE76+BX76 -> 0
D78: 0 | G78: 0 | J78: 0 | M78: 0 | P78: =SUM(D78:M78) -> 0 | W78: 0 | Z78: 0 | AC78: 0 | AF78: 0 | AI78: =SUM(W78:AF78) -> 0 | AP78: 0 | AS78: 0 | AV78: 0 | AY78: 0 | BB78: =SUM(AP78:AY78) -> 0 | BI78: 0 | BL78: 0 | BO78: 0 | BR78: 0 | BU78: =SUM(BI78:BR78) -> 0 | CB78: =+D78+W78+AP78+BI78 -> 0 | CE78: =+G78+Z78+AS78+BL78 -> 0 | CH78: =+J78+AC78+AV78+BO78 -> 0 | CK78: =+M78+AF78+AY78+BR78 -> 0 | CN78: =SUM(CB78:CK78) -> 0 | CQ78: =+S78+AL78+BE78+BX78 -> 0

Sheet Reducción Gastos
A2: REDUCCIÓN DE GASTOS | D2: Subproyecto 1 | T2: Subproyecto 2 | AJ2: Subproyecto 3 | AZ2: Subproyecto 4 | BP2: PROYECTO GLOBAL
D4: TRIPMATE | T4: =+Definición!C11 -> [Nombre ] | AJ4: =+Definición!C18 -> [Nombre ] | AZ4: =+Definición!C25 -> [Nombre ] | BP4: =+Definición!C2 -> TRIPMATE
D6: Año 1 | G6: Año 2 | J6: Año 3 | M6: Año 4 | P6: Total | T6: Año 1 | W6: Año 2 | Z6: Año 3 | AC6: Año 4 | AF6: Total | AJ6: Año 1 | AM6: Año 2 | AP6: Año 3 | AS6: Año 4 | AV6: Total | AZ6: Año 1 | BC6: Año 2 | BF6: Año 3 | BI6: Año 4 | BL6: Total | BP6: Año 1 | BS6: Año 2 | BV6: Año 3 | BY6: Año 4 | CB6: Total
A9: TOTAL Ñ GASTOS | D9: =+D12+D35+D58 -> 449000 | G9: =+G12+G35+G58 -> 2469000 | J9: =+J12+J35+J58 -> 3119000 | M9: =+M12+M35+M58 -> 7089000 | P9: =SUM(P11:P80)/2 -> 13126000 | T9: =+T12+T35+T58 -> 0 | W9: =+W12+W35+W58 -> 0 | Z9: =+Z12+Z35+Z58 -> 0 | AC9: =+AC12+AC35+AC58 -> 0 | AF9: =SUM(AF11:AF80)/2 -> 0 | AJ9: =+AJ12+AJ35+AJ58 -> 0 | AM9: =+AM12+AM35+AM58 -> 0 | AP9: =+AP12+AP35+AP58 -> 0 | AS9: =+AS12+AS35+AS58 -> 0 | AV9: =SUM(AV11:AV80)/2 -> 0 | AZ9: =+AZ12+AZ35+AZ58 -> 0 | BC9: =+BC12+BC35+BC58 -> 0 | BF9: =+BF12+BF35+BF58 -> 0 | BI9: =+BI12+BI35+BI58 -> 0 | BL9: =SUM(BL11:BL80)/2 -> 0 | BP9: =+BP12+BP35+BP58 -> 449000 | BS9: =+BS12+BS35+BS58 -> 2469000 | BV9: =+BV12+BV35+BV58 -> 3119000 | BY9: =+BY12+BY35+BY58 -> 7089000 | CB9: =SUM(CB11:CB80)/2 -> 13126000
A12: Costes de Estructura | D12: =SUM(D14:D33) -> 449000 | G12: =SUM(G14:G33) -> 489000 | J12: =SUM(J14:J33) -> 509000 | M12: =SUM(M14:M33) -> 539000 | P12: =SUM(P14:P33) -> 1986000 | T12: =SUM(T14:T33) -> 0 | W12: =SUM(W14:W33) -> 0 | Z12: =SUM(Z14:Z33) -> 0 | AC12: =SUM(AC14:AC33) -> 0 | AF12: =SUM(AF14:AF33) -> 0 | AJ12: =SUM(AJ14:AJ33) -> 0 | AM12: =SUM(AM14:AM33) -> 0 | AP12: =SUM(AP14:AP33) -> 0 | AS12: =SUM(AS14:AS33) -> 0 | AV12: =SUM(AV14:AV33) -> 0 | AZ12: =SUM(AZ14:AZ33) -> 0 | BC12: =SUM(BC14:BC33) -> 0 | BF12: =SUM(BF14:BF33) -> 0 | BI12: =SUM(BI14:BI33) -> 0 | BL12: =SUM(BL14:BL33) -> 0 | BP12: =SUM(BP14:BP33) -> 449000 | BS12: =SUM(BS14:BS33) -> 489000 | BV12: =SUM(BV14:BV33) -> 509000 | BY12: =SUM(BY14:BY33) -> 539000 | CB12: =SUM(CB14:CB33) -> 1986000
A14: SUELDOS Y SALARIOS | D14: 350000 | G14: 350000 | J14: 350000 | M14: 350000 | P14: =SUM(D14:M14) -> 1400000 | T14: 0 | W14: 0 | Z14: 0 | AC14: 0 | AF14: =SUM(T14:AC14) -> 0 | AJ14: 0 | AM14: 0 | AP14: 0 | AS14: 0 | AV14: =SUM(AJ14:AS14) -> 0 | AZ14: 0 | BC14: 0 | BF14: 0 | BI14: 0 | BL14: =SUM(AZ14:BI14) -> 0 | BP14: =+D14+T14+AJ14+AZ14 -> 350000 | BS14: =+G14+W14+AM14+BC14 -> 350000 | BV14: =+J14+Z14+AP14+BF14 -> 350000 | BY14: =+M14+AC14+AS14+BI14 -> 350000 | CB14: =SUM(BP14:BY14) -> 1400000
A16: COMUNICACIONES | D16: 60000 | G16: 100000 | J16: 120000 | M16: 150000 | P16: =SUM(D16:M16) -> 430000 | T16: 0 | W16: 0 | Z16: 0 | AC16: 0 | AF16: =SUM(T16:AC16) -> 0 | AJ16: 0 | AM16: 0 | AP16: 0 | AS16: 0 | AV16: =SUM(AJ16:AS16) -> 0 | AZ16: 0 | BC16: 0 | BF16: 0 | BI16: 0 | BL16: =SUM(AZ16:BI16) -> 0 | BP16: =+D16+T16+AJ16+AZ16 -> 60000 | BS16: =+G16+W16+AM16+BC16 -> 100000 | BV16: =+J16+Z16+AP16+BF16 -> 120000 | BY16: =+M16+AC16+AS16+BI16 -> 150000 | CB16: =SUM(BP16:BY16) -> 430000
A18: ALQUILERES | D18: 24000 | G18: 24000 | J18: 24000 | M18: 24000 | P18: =SUM(D18:M18) -> 96000 | T18: 0 | W18: 0 | Z18: 0 | AC18: 0 | AF18: =SUM(T18:AC18) -> 0 | AJ18: 0 | AM18: 0 | AP18: 0 | AS18: 0 | AV18: =SUM(AJ18:AS18) -> 0 | AZ18: 0 | BC18: 0 | BF18: 0 | BI18: 0 | BL18: =SUM(AZ18:BI18) -> 0 | BP18: =+D18+T18+AJ18+AZ18 -> 24000 | BS18: =+G18+W18+AM18+BC18 -> 24000 | BV18: =+J18+Z18+AP18+BF18 -> 24000 | BY18: =+M18+AC18+AS18+BI18 -> 24000 | CB18: =SUM(BP18:BY18) -> 96000
A20: GESTORIA Y ASESOR FISCAL | D20: 15000 | G20: 15000 | J20: 15000 | M20: 15000 | P20: =SUM(D20:M20) -> 60000 | T20: 0 | W20: 0 | Z20: 0 | AC20: 0 | AF20: =SUM(T20:AC20) -> 0 | AJ20: 0 | AM20: 0 | AP20: 0 | AS20: 0 | AV20: =SUM(AJ20:AS20) -> 0 | AZ20: 0 | BC20: 0 | BF20: 0 | BI20: 0 | BL20: =SUM(AZ20:BI20) -> 0 | BP20: =+D20+T20+AJ20+AZ20 -> 15000 | BS20: =+G20+W20+AM20+BC20 -> 15000 | BV20: =+J20+Z20+AP20+BF20 -> 15000 | BY20: =+M20+AC20+AS20+BI20 -> 15000 | CB20: =SUM(BP20:BY20) -> 60000
D22: 0 | G22: 0 | J22: 0 | M22: 0 | P22: =SUM(D22:M22) -> 0 | T22: 0 | W22: 0 | Z22: 0 | AC22: 0 | AF22: =SUM(T22:AC22) -> 0 | AJ22: 0 | AM22: 0 | AP22: 0 | AS22: 0 | AV22: =SUM(AJ22:AS22) -> 0 | AZ22: 0 | BC22: 0 | BF22: 0 | BI22: 0 | BL22: =SUM(AZ22:BI22) -> 0 | BP22: =+D22+T22+AJ22+AZ22 -> 0 | BS22: =+G22+W22+AM22+BC22 -> 0 | BV22: =+J22+Z22+AP22+BF22 -> 0 | BY22: =+M22+AC22+AS22+BI22 -> 0 | CB22: =SUM(BP22:BY22) -> 0
D24: 0 | G24: 0 | J24: 0 | M24: 0 | P24: =SUM(D24:M24) -> 0 | T24: 0 | W24: 0 | Z24: 0 | AC24: 0 | AF24: =SUM(T24:AC24) -> 0 | AJ24: 0 | AM24: 0 | AP24: 0 | AS24: 0 | AV24: =SUM(AJ24:AS24) -> 0 | AZ24: 0 | BC24: 0 | BF24: 0 | BI24: 0 | BL24: =SUM(AZ24:BI24) -> 0 | BP24: =+D24+T24+AJ24+AZ24 -> 0 | BS24: =+G24+W24+AM24+BC24 -> 0 | BV24: =+J24+Z24+AP24+BF24 -> 0 | BY24: =+M24+AC24+AS24+BI24 -> 0 | CB24: =SUM(BP24:BY24) -> 0
D26: 0 | G26: 0 | J26: 0 | M26: 0 | P26: =SUM(D26:M26) -> 0 | T26: 0 | W26: 0 | Z26: 0 | AC26: 0 | AF26: =SUM(T26:AC26) -> 0 | AJ26: 0 | AM26: 0 | AP26: 0 | AS26: 0 | AV26: =SUM(AJ26:AS26) -> 0 | AZ26: 0 | BC26: 0 | BF26: 0 | BI26: 0 | BL26: =SUM(AZ26:BI26) -> 0 | BP26: =+D26+T26+AJ26+AZ26 -> 0 | BS26: =+G26+W26+AM26+BC26 -> 0 | BV26: =+J26+Z26+AP26+BF26 -> 0 | BY26: =+M26+AC26+AS26+BI26 -> 0 | CB26: =SUM(BP26:BY26) -> 0
D28: 0 | G28: 0 | J28: 0 | M28: 0 | P28: =SUM(D28:M28) -> 0 | T28: 0 | W28: 0 | Z28: 0 | AC28: 0 | AF28: =SUM(T28:AC28) -> 0 | AJ28: 0 | AM28: 0 | AP28: 0 | AS28: 0 | AV28: =SUM(AJ28:AS28) -> 0 | AZ28: 0 | BC28: 0 | BF28: 0 | BI28: 0 | BL28: =SUM(AZ28:BI28) -> 0 | BP28: =+D28+T28+AJ28+AZ28 -> 0 | BS28: =+G28+W28+AM28+BC28 -> 0 | BV28: =+J28+Z28+AP28+BF28 -> 0 | BY28: =+M28+AC28+AS28+BI28 -> 0 | CB28: =SUM(BP28:BY28) -> 0
D30: 0 | G30: 0 | J30: 0 | M30: 0 | P30: =SUM(D30:M30) -> 0 | T30: 0 | W30: 0 | Z30: 0 | AC30: 0 | AF30: =SUM(T30:AC30) -> 0 | AJ30: 0 | AM30: 0 | AP30: 0 | AS30: 0 | AV30: =SUM(AJ30:AS30) -> 0 | AZ30: 0 | BC30: 0 | BF30: 0 | BI30: 0 | BL30: =SUM(AZ30:BI30) -> 0 | BP30: =+D30+T30+AJ30+AZ30 -> 0 | BS30: =+G30+W30+AM30+BC30 -> 0 | BV30: =+J30+Z30+AP30+BF30 -> 0 | BY30: =+M30+AC30+AS30+BI30 -> 0 | CB30: =SUM(BP30:BY30) -> 0
D32: 0 | G32: 0 | J32: 0 | M32: 0 | P32: =SUM(D32:M32) -> 0 | T32: 0 | W32: 0 | Z32: 0 | AC32: 0 | AF32: =SUM(T32:AC32) -> 0 | AJ32: 0 | AM32: 0 | AP32: 0 | AS32: 0 | AV32: =SUM(AJ32:AS32) -> 0 | AZ32: 0 | BC32: 0 | BF32: 0 | BI32: 0 | BL32: =SUM(AZ32:BI32) -> 0 | BP32: =+D32+T32+AJ32+AZ32 -> 0 | BS32: =+G32+W32+AM32+BC32 -> 0 | BV32: =+J32+Z32+AP32+BF32 -> 0 | BY32: =+M32+AC32+AS32+BI32 -> 0 | CB32: =SUM(BP32:BY32) -> 0
A35: Costes Comerciales | D35: =SUM(D37:D56) -> 0 | G35: =SUM(G37:G56) -> 180000 | J35: =SUM(J37:J56) -> 210000 | M35: =SUM(M37:M56) -> 250000 | P35: =SUM(P37:P56) -> 640000 | T35: =SUM(T37:T56) -> 0 | W35: =SUM(W37:W56) -> 0 | Z35: =SUM(Z37:Z56) -> 0 | AC35: =SUM(AC37:AC56) -> 0 | AF35: =SUM(AF37:AF56) -> 0 | AJ35: =SUM(AJ37:AJ56) -> 0 | AM35: =SUM(AM37:AM56) -> 0 | AP35: =SUM(AP37:AP56) -> 0 | AS35: =SUM(AS37:AS56) -> 0 | AV35: =SUM(AV37:AV56) -> 0 | AZ35: =SUM(AZ37:AZ56) -> 0 | BC35: =SUM(BC37:BC56) -> 0 | BF35: =SUM(BF37:BF56) -> 0 | BI35: =SUM(BI37:BI56) -> 0 | BL35: =SUM(BL37:BL56) -> 0 | BP35: =SUM(BP37:BP56) -> 0 | BS35: =SUM(BS37:BS56) -> 180000 | BV35: =SUM(BV37:BV56) -> 210000 | BY35: =SUM(BY37:BY56) -> 250000 | CB35: =SUM(CB37:CB56) -> 640000
A37: PROMOCION Y PUBLICIDAD | D37: 0 | G37: 180000 | J37: 210000 | M37: 250000 | P37: =SUM(D37:M37) -> 640000 | T37: 0 | W37: 0 | Z37: 0 | AC37: 0 | AF37: =SUM(T37:AC37) -> 0 | AJ37: 0 | AM37: 0 | AP37: 0 | AS37: 0 | AV37: =SUM(AJ37:AS37) -> 0 | AZ37: 0 | BC37: 0 | BF37: 0 | BI37: 0 | BL37: =SUM(AZ37:BI37) -> 0 | BP37: =+D37+T37+AJ37+AZ37 -> 0 | BS37: =+G37+W37+AM37+BC37 -> 180000 | BV37: =+J37+Z37+AP37+BF37 -> 210000 | BY37: =+M37+AC37+AS37+BI37 -> 250000 | CB37: =SUM(BP37:BY37) -> 640000
D39: 0 | G39: 0 | J39: 0 | M39: 0 | P39: =SUM(D39:M39) -> 0 | T39: 0 | W39: 0 | Z39: 0 | AC39: 0 | AF39: =SUM(T39:AC39) -> 0 | AJ39: 0 | AM39: 0 | AP39: 0 | AS39: 0 | AV39: =SUM(AJ39:AS39) -> 0 | AZ39: 0 | BC39: 0 | BF39: 0 | BI39: 0 | BL39: =SUM(AZ39:BI39) -> 0 | BP39: =+D39+T39+AJ39+AZ39 -> 0 | BS39: =+G39+W39+AM39+BC39 -> 0 | BV39: =+J39+Z39+AP39+BF39 -> 0 | BY39: =+M39+AC39+AS39+BI39 -> 0 | CB39: =SUM(BP39:BY39) -> 0
D41: 0 | G41: 0 | J41: 0 | M41: 0 | P41: =SUM(D41:M41) -> 0 | T41: 0 | W41: 0 | Z41: 0 | AC41: 0 | AF41: =SUM(T41:AC41) -> 0 | AJ41: 0 | AM41: 0 | AP41: 0 | AS41: 0 | AV41: =SUM(AJ41:AS41) -> 0 | AZ41: 0 | BC41: 0 | BF41: 0 | BI41: 0 | BL41: =SUM(AZ41:BI41) -> 0 | BP41: =+D41+T41+AJ41+AZ41 -> 0 | BS41: =+G41+W41+AM41+BC41 -> 0 | BV41: =+J41+Z41+AP41+BF41 -> 0 | BY41: =+M41+AC41+AS41+BI41 -> 0 | CB41: =SUM(BP41:BY41) -> 0
D43: 0 | G43: 0 | J43: 0 | M43: 0 | P43: =SUM(D43:M43) -> 0 | T43: 0 | W43: 0 | Z43: 0 | AC43: 0 | AF43: =SUM(T43:AC43) -> 0 | AJ43: 0 | AM43: 0 | AP43: 0 | AS43: 0 | AV43: =SUM(AJ43:AS43) -> 0 | AZ43: 0 | BC43: 0 | BF43: 0 | BI43: 0 | BL43: =SUM(AZ43:BI43) -> 0 | BP43: =+D43+T43+AJ43+AZ43 -> 0 | BS43: =+G43+W43+AM43+BC43 -> 0 | BV43: =+J43+Z43+AP43+BF43 -> 0 | BY43: =+M43+AC43+AS43+BI43 -> 0 | CB43: =SUM(BP43:BY43) -> 0
D45: 0 | G45: 0 | J45: 0 | M45: 0 | P45: =SUM(D45:M45) -> 0 | T45: 0 | W45: 0 | Z45: 0 | AC45: 0 | AF45: =SUM(T45:AC45) -> 0 | AJ45: 0 | AM45: 0 | AP45: 0 | AS45: 0 | AV45: =SUM(AJ45:AS45) -> 0 | AZ45: 0 | BC45: 0 | BF45: 0 | BI45: 0 | BL45: =SUM(AZ45:BI45) -> 0 | BP45: =+D45+T45+AJ45+AZ45 -> 0 | BS45: =+G45+W45+AM45+BC45 -> 0 | BV45: =+J45+Z45+AP45+BF45 -> 0 | BY45: =+M45+AC45+AS45+BI45 -> 0 | CB45: =SUM(BP45:BY45) -> 0
D47: 0 | G47: 0 | J47: 0 | M47: 0 | P47: =SUM(D47:M47) -> 0 | T47: 0 | W47: 0 | Z47: 0 | AC47: 0 | AF47: =SUM(T47:AC47) -> 0 | AJ47: 0 | AM47: 0 | AP47: 0 | AS47: 0 | AV47: =SUM(AJ47:AS47) -> 0 | AZ47: 0 | BC47: 0 | BF47: 0 | BI47: 0 | BL47: =SUM(AZ47:BI47) -> 0 | BP47: =+D47+T47+AJ47+AZ47 -> 0 | BS47: =+G47+W47+AM47+BC47 -> 0 | BV47: =+J47+Z47+AP47+BF47 -> 0 | BY47: =+M47+AC47+AS47+BI47 -> 0 | CB47: =SUM(BP47:BY47) -> 0
D49: 0 | G49: 0 | J49: 0 | M49: 0 | P49: =SUM(D49:M49) -> 0 | T49: 0 | W49: 0 | Z49: 0 | AC49: 0 | AF49: =SUM(T49:AC49) -> 0 | AJ49: 0 | AM49: 0 | AP49: 0 | AS49: 0 | AV49: =SUM(AJ49:AS49) -> 0 | AZ49: 0 | BC49: 0 | BF49: 0 | BI49: 0 | BL49: =SUM(AZ49:BI49) -> 0 | BP49: =+D49+T49+AJ49+AZ49 -> 0 | BS49: =+G49+W49+AM49+BC49 -> 0 | BV49: =+J49+Z49+AP49+BF49 -> 0 | BY49: =+M49+AC49+AS49+BI49 -> 0 | CB49: =SUM(BP49:BY49) -> 0
D51: 0 | G51: 0 | J51: 0 | M51: 0 | P51: =SUM(D51:M51) -> 0 | T51: 0 | W51: 0 | Z51: 0 | AC51: 0 | AF51: =SUM(T51:AC51) -> 0 | AJ51: 0 | AM51: 0 | AP51: 0 | AS51: 0 | AV51: =SUM(AJ51:AS51) -> 0 | AZ51: 0 | BC51: 0 | BF51: 0 | BI51: 0 | BL51: =SUM(AZ51:BI51) -> 0 | BP51: =+D51+T51+AJ51+AZ51 -> 0 | BS51: =+G51+W51+AM51+BC51 -> 0 | BV51: =+J51+Z51+AP51+BF51 -> 0 | BY51: =+M51+AC51+AS51+BI51 -> 0 | CB51: =SUM(BP51:BY51) -> 0
D53: 0 | G53: 0 | J53: 0 | M53: 0 | P53: =SUM(D53:M53) -> 0 | T53: 0 | W53: 0 | Z53: 0 | AC53: 0 | AF53: =SUM(T53:AC53) -> 0 | AJ53: 0 | AM53: 0 | AP53: 0 | AS53: 0 | AV53: =SUM(AJ53:AS53) -> 0 | AZ53: 0 | BC53: 0 | BF53: 0 | BI53: 0 | BL53: =SUM(AZ53:BI53) -> 0 | BP53: =+D53+T53+AJ53+AZ53 -> 0 | BS53: =+G53+W53+AM53+BC53 -> 0 | BV53: =+J53+Z53+AP53+BF53 -> 0 | BY53: =+M53+AC53+AS53+BI53 -> 0 | CB53: =SUM(BP53:BY53) -> 0
D55: 0 | G55: 0 | J55: 0 | M55: 0 | P55: =SUM(D55:M55) -> 0 | T55: 0 | W55: 0 | Z55: 0 | AC55: 0 | AF55: =SUM(T55:AC55) -> 0 | AJ55: 0 | AM55: 0 | AP55: 0 | AS55: 0 | AV55: =SUM(AJ55:AS55) -> 0 | AZ55: 0 | BC55: 0 | BF55: 0 | BI55: 0 | BL55: =SUM(AZ55:BI55) -> 0 | BP55: =+D55+T55+AJ55+AZ55 -> 0 | BS55: =+G55+W55+AM55+BC55 -> 0 | BV55: =+J55+Z55+AP55+BF55 -> 0 | BY55: =+M55+AC55+AS55+BI55 -> 0 | CB55: =SUM(BP55:BY55) -> 0
A58: Costes de Captación | D58: =SUM(D60:D79) -> 0 | G58: =SUM(G60:G79) -> 1800000 | J58: =SUM(J60:J79) -> 2400000 | M58: =SUM(M60:M79) -> 6300000 | P58: =SUM(P60:P79) -> 10500000 | T58: =SUM(T60:T79) -> 0 | W58: =SUM(W60:W79) -> 0 | Z58: =SUM(Z60:Z79) -> 0 | AC58: =SUM(AC60:AC79) -> 0 | AF58: =SUM(AF60:AF79) -> 0 | AJ58: =SUM(AJ60:AJ79) -> 0 | AM58: =SUM(AM60:AM79) -> 0 | AP58: =SUM(AP60:AP79) -> 0 | AS58: =SUM(AS60:AS79) -> 0 | AV58: =SUM(AV60:AV79) -> 0 | AZ58: =SUM(AZ60:AZ79) -> 0 | BC58: =SUM(BC60:BC79) -> 0 | BF58: =SUM(BF60:BF79) -> 0 | BI58: =SUM(BI60:BI79) -> 0 | BL58: =SUM(BL60:BL79) -> 0 | BP58: =SUM(BP60:BP79) -> 0 | BS58: =SUM(BS60:BS79) -> 1800000 | BV58: =SUM(BV60:BV79) -> 2400000 | BY58: =SUM(BY60:BY79) -> 6300000 | CB58: =SUM(CB60:CB79) -> 10500000
A60: CPL/CPA | D60: 0 | G60: 1800000 | J60: 2400000 | M60: 6300000 | P60: =SUM(D60:M60) -> 10500000 | T60: 0 | W60: 0 | Z60: 0 | AC60: 0 | AF60: =SUM(T60:AC60) -> 0 | AJ60: 0 | AM60: 0 | AP60: 0 | AS60: 0 | AV60: =SUM(AJ60:AS60) -> 0 | AZ60: 0 | BC60: 0 | BF60: 0 | BI60: 0 | BL60: =SUM(AZ60:BI60) -> 0 | BP60: =+D60+T60+AJ60+AZ60 -> 0 | BS60: =+G60+W60+AM60+BC60 -> 1800000 | BV60: =+J60+Z60+AP60+BF60 -> 2400000 | BY60: =+M60+AC60+AS60+BI60 -> 6300000 | CB60: =SUM(BP60:BY60) -> 10500000
D62: 0 | G62: 0 | J62: 0 | M62: 0 | P62: =SUM(D62:M62) -> 0 | T62: 0 | W62: 0 | Z62: 0 | AC62: 0 | AF62: =SUM(T62:AC62) -> 0 | AJ62: 0 | AM62: 0 | AP62: 0 | AS62: 0 | AV62: =SUM(AJ62:AS62) -> 0 | AZ62: 0 | BC62: 0 | BF62: 0 | BI62: 0 | BL62: =SUM(AZ62:BI62) -> 0 | BP62: =+D62+T62+AJ62+AZ62 -> 0 | BS62: =+G62+W62+AM62+BC62 -> 0 | BV62: =+J62+Z62+AP62+BF62 -> 0 | BY62: =+M62+AC62+AS62+BI62 -> 0 | CB62: =SUM(BP62:BY62) -> 0
D64: 0 | G64: 0 | J64: 0 | M64: 0 | P64: =SUM(D64:M64) -> 0 | T64: 0 | W64: 0 | Z64: 0 | AC64: 0 | AF64: =SUM(T64:AC64) -> 0 | AJ64: 0 | AM64: 0 | AP64: 0 | AS64: 0 | AV64: =SUM(AJ64:AS64) -> 0 | AZ64: 0 | BC64: 0 | BF64: 0 | BI64: 0 | BL64: =SUM(AZ64:BI64) -> 0 | BP64: =+D64+T64+AJ64+AZ64 -> 0 | BS64: =+G64+W64+AM64+BC64 -> 0 | BV64: =+J64+Z64+AP64+BF64 -> 0 | BY64: =+M64+AC64+AS64+BI64 -> 0 | CB64: =SUM(BP64:BY64) -> 0
D66: 0 | G66: 0 | J66: 0 | M66: 0 | P66: =SUM(D66:M66) -> 0 | T66: 0 | W66: 0 | Z66: 0 | AC66: 0 | AF66: =SUM(T66:AC66) -> 0 | AJ66: 0 | AM66: 0 | AP66: 0 | AS66: 0 | AV66: =SUM(AJ66:AS66) -> 0 | AZ66: 0 | BC66: 0 | BF66: 0 | BI66: 0 | BL66: =SUM(AZ66:BI66) -> 0 | BP66: =+D66+T66+AJ66+AZ66 -> 0 | BS66: =+G66+W66+AM66+BC66 -> 0 | BV66: =+J66+Z66+AP66+BF66 -> 0 | BY66: =+M66+AC66+AS66+BI66 -> 0 | CB66: =SUM(BP66:BY66) -> 0
D68: 0 | G68: 0 | J68: 0 | M68: 0 | P68: =SUM(D68:M68) -> 0 | T68: 0 | W68: 0 | Z68: 0 | AC68: 0 | AF68: =SUM(T68:AC68) -> 0 | AJ68: 0 | AM68: 0 | AP68: 0 | AS68: 0 | AV68: =SUM(AJ68:AS68) -> 0 | AZ68: 0 | BC68: 0 | BF68: 0 | BI68: 0 | BL68: =SUM(AZ68:BI68) -> 0 | BP68: =+D68+T68+AJ68+AZ68 -> 0 | BS68: =+G68+W68+AM68+BC68 -> 0 | BV68: =+J68+Z68+AP68+BF68 -> 0 | BY68: =+M68+AC68+AS68+BI68 -> 0 | CB68: =SUM(BP68:BY68) -> 0
D70: 0 | G70: 0 | J70: 0 | M70: 0 | P70: =SUM(D70:M70) -> 0 | T70: 0 | W70: 0 | Z70: 0 | AC70: 0 | AF70: =SUM(T70:AC70) -> 0 | AJ70: 0 | AM70: 0 | AP70: 0 | AS70: 0 | AV70: =SUM(AJ70:AS70) -> 0 | AZ70: 0 | BC70: 0 | BF70: 0 | BI70: 0 | BL70: =SUM(AZ70:BI70) -> 0 | BP70: =+D70+T70+AJ70+AZ70 -> 0 | BS70: =+G70+W70+AM70+BC70 -> 0 | BV70: =+J70+Z70+AP70+BF70 -> 0 | BY70: =+M70+AC70+AS70+BI70 -> 0 | CB70: =SUM(BP70:BY70) -> 0
D72: 0 | G72: 0 | J72: 0 | M72: 0 | P72: =SUM(D72:M72) -> 0 | T72: 0 | W72: 0 | Z72: 0 | AC72: 0 | AF72: =SUM(T72:AC72) -> 0 | AJ72: 0 | AM72: 0 | AP72: 0 | AS72: 0 | AV72: =SUM(AJ72:AS72) -> 0 | AZ72: 0 | BC72: 0 | BF72: 0 | BI72: 0 | BL72: =SUM(AZ72:BI72) -> 0 | BP72: =+D72+T72+AJ72+AZ72 -> 0 | BS72: =+G72+W72+AM72+BC72 -> 0 | BV72: =+J72+Z72+AP72+BF72 -> 0 | BY72: =+M72+AC72+AS72+BI72 -> 0 | CB72: =SUM(BP72:BY72) -> 0
D74: 0 | G74: 0 | J74: 0 | M74: 0 | P74: =SUM(D74:M74) -> 0 | T74: 0 | W74: 0 | Z74: 0 | AC74: 0 | AF74: =SUM(T74:AC74) -> 0 | AJ74: 0 | AM74: 0 | AP74: 0 | AS74: 0 | AV74: =SUM(AJ74:AS74) -> 0 | AZ74: 0 | BC74: 0 | BF74: 0 | BI74: 0 | BL74: =SUM(AZ74:BI74) -> 0 | BP74: =+D74+T74+AJ74+AZ74 -> 0 | BS74: =+G74+W74+AM74+BC74 -> 0 | BV74: =+J74+Z74+AP74+BF74 -> 0 | BY74: =+M74+AC74+AS74+BI74 -> 0 | CB74: =SUM(BP74:BY74) -> 0
D76: 0 | G76: 0 | J76: 0 | M76: 0 | P76: =SUM(D76:M76) -> 0 | T76: 0 | W76: 0 | Z76: 0 | AC76: 0 | AF76: =SUM(T76:AC76) -> 0 | AJ76: 0 | AM76: 0 | AP76: 0 | AS76: 0 | AV76: =SUM(AJ76:AS76) -> 0 | AZ76: 0 | BC76: 0 | BF76: 0 | BI76: 0 | BL76: =SUM(AZ76:BI76) -> 0 | BP76: =+D76+T76+AJ76+AZ76 -> 0 | BS76: =+G76+W76+AM76+BC76 -> 0 | BV76: =+J76+Z76+AP76+BF76 -> 0 | BY76: =+M76+AC76+AS76+BI76 -> 0 | CB76: =SUM(BP76:BY76) -> 0
D78: 0 | G78: 0 | J78: 0 | M78: 0 | P78: =SUM(D78:M78) -> 0 | T78: 0 | W78: 0 | Z78: 0 | AC78: 0 | AF78: =SUM(T78:AC78) -> 0 | AJ78: 0 | AM78: 0 | AP78: 0 | AS78: 0 | AV78: =SUM(AJ78:AS78) -> 0 | AZ78: 0 | BC78: 0 | BF78: 0 | BI78: 0 | BL78: =SUM(AZ78:BI78) -> 0 | BP78: =+D78+T78+AJ78+AZ78 -> 0 | BS78: =+G78+W78+AM78+BC78 -> 0 | BV78: =+J78+Z78+AP78+BF78 -> 0 | BY78: =+M78+AC78+AS78+BI78 -> 0 | CB78: =SUM(BP78:BY78) -> 0

Sheet Ingresos
A2: INCREMENTO DE INGRESOS | D2: Subproyecto 1 | T2: Subproyecto 2 | AJ2: Subproyecto 3 | AZ2: Subproyecto 4 | BP2: PROYECTO GLOBAL
D4: =+Definición!C4 -> TRIPMATE | T4: =+Definición!C11 -> [Nombre ] | AJ4: =+Definición!C18 -> [Nombre ] | AZ4: =+Definición!C25 -> [Nombre ] | BP4: =+Definición!C2 -> TRIPMATE
D6: Año 1 | G6: Año 2 | J6: Año 3 | M6: Año 4 | P6: Total | T6: Año 1 | W6: Año 2 | Z6: Año 3 | AC6: Año 4 | AF6: Total | AJ6: Año 1 | AM6: Año 2 | AP6: Año 3 | AS6: Año 4 | AV6: Total | AZ6: Año 1 | BC6: Año 2 | BF6: Año 3 | BI6: Año 4 | BL6: Total | BP6: Año 1 | BS6: Año 2 | BV6: Año 3 | BY6: Año 4 | CB6: Total
A9: TOTAL D INGRESOS | D9: =SUM(D11:D80)/2 -> 0 | G9: =SUM(G11:G80)/2 -> 1706580 | J9: =SUM(J11:J80)/2 -> 4418020 | M9: =SUM(M11:M80)/2 -> 12422550 | P9: =SUM(P11:P80)/2 -> 18547150 | T9: =SUM(T11:T80)/2 -> 0 | W9: =SUM(W11:W80)/2 -> 0 | Z9: =SUM(Z11:Z80)/2 -> 0 | AC9: =SUM(AC11:AC80)/2 -> 0 | AF9: =SUM(AF11:AF80)/2 -> 0 | AJ9: =SUM(AJ11:AJ80)/2 -> 0 | AM9: =SUM(AM11:AM80)/2 -> 0 | AP9: =SUM(AP11:AP80)/2 -> 0 | AS9: =SUM(AS11:AS80)/2 -> 0 | AV9: =SUM(AV11:AV80)/2 -> 0 | AZ9: =SUM(AZ11:AZ80)/2 -> 0 | BC9: =SUM(BC11:BC80)/2 -> 0 | BF9: =SUM(BF11:BF80)/2 -> 0 | BI9: =SUM(BI11:BI80)/2 -> 0 | BL9: =SUM(BL11:BL80)/2 -> 0 | BP9: =SUM(BP11:BP80)/2 -> 0 | BS9: =SUM(BS11:BS80)/2 -> 1706580 | BV9: =SUM(BV11:BV80)/2 -> 4418020 | BY9: =SUM(BY11:BY80)/2 -> 12422550 | CB9: =SUM(CB11:CB80)/2 -> 18547150
A12: Incremento de ventas | D12: =SUM(D14:D33) -> 0 | G12: =SUM(G14:G33) -> 1706580 | J12: =SUM(J14:J33) -> 4318020 | M12: =SUM(M14:M33) -> 12272550 | P12: =SUM(P14:P33) -> 18297150 | T12: =SUM(T14:T33) -> 0 | W12: =SUM(W14:W33) -> 0 | Z12: =SUM(Z14:Z33) -> 0 | AC12: =SUM(AC14:AC33) -> 0 | AF12: =SUM(AF14:AF33) -> 0 | AJ12: =SUM(AJ14:AJ33) -> 0 | AM12: =SUM(AM14:AM33) -> 0 | AP12: =SUM(AP14:AP33) -> 0 | AS12: =SUM(AS14:AS33) -> 0 | AV12: =SUM(AV14:AV33) -> 0 | AZ12: =SUM(AZ14:AZ33) -> 0 | BC12: =SUM(BC14:BC33) -> 0 | BF12: =SUM(BF14:BF33) -> 0 | BI12: =SUM(BI14:BI33) -> 0 | BL12: =SUM(BL14:BL33) -> 0 | BP12: =SUM(BP14:BP33) -> 0 | BS12: =SUM(BS14:BS33) -> 1706580 | BV12: =SUM(BV14:BV33) -> 4318020 | BY12: =SUM(BY14:BY33) -> 12272550 | CB12: =SUM(CB14:CB33) -> 18297150
A14: DESCARGAS APP PREMIUM | G14: 293580 | J14: 685020 | M14: 1712550 | P14: =SUM(D14:M14) -> 2691150 | T14: 0 | W14: 0 | Z14: 0 | AC14: 0 | AF14: =SUM(T14:AC14) -> 0 | AJ14: 0 | AM14: 0 | AP14: 0 | AS14: 0 | AV14: =SUM(AJ14:AS14) -> 0 | AZ14: 0 | BC14: 0 | BF14: 0 | BI14: 0 | BL14: =SUM(AZ14:BI14) -> 0 | BP14: =+D14+T14+AJ14+AZ14 -> 0 | BS14: =+G14+W14+AM14+BC14 -> 293580 | BV14: =+J14+Z14+AP14+BF14 -> 685020 | BY14: =+M14+AC14+AS14+BI14 -> 1712550 | CB14: =SUM(BP14:BY14) -> 2691150
A16: CUOTA PREMIUM LOCALES | G16: 585000 | J16: 1365000 | M16: 1950000 | P16: =SUM(D16:M16) -> 3900000 | T16: 0 | W16: 0 | Z16: 0 | AC16: 0 | AF16: =SUM(T16:AC16) -> 0 | AJ16: 0 | AM16: 0 | AP16: 0 | AS16: 0 | AV16: =SUM(AJ16:AS16) -> 0 | AZ16: 0 | BC16: 0 | BF16: 0 | BI16: 0 | BL16: =SUM(AZ16:BI16) -> 0 | BP16: =+D16+T16+AJ16+AZ16 -> 0 | BS16: =+G16+W16+AM16+BC16 -> 585000 | BV16: =+J16+Z16+AP16+BF16 -> 1365000 | BY16: =+M16+AC16+AS16+BI16 -> 1950000 | CB16: =SUM(BP16:BY16) -> 3900000
A18: INGRESOS POR USUARIO | G18: 828000 | J18: 2268000 | M18: 8610000 | P18: =SUM(D18:M18) -> 11706000 | T18: 0 | W18: 0 | Z18: 0 | AC18: 0 | AF18: =SUM(T18:AC18) -> 0 | AJ18: 0 | AM18: 0 | AP18: 0 | AS18: 0 | AV18: =SUM(AJ18:AS18) -> 0 | AZ18: 0 | BC18: 0 | BF18: 0 | BI18: 0 | BL18: =SUM(AZ18:BI18) -> 0 | BP18: =+D18+T18+AJ18+AZ18 -> 0 | BS18: =+G18+W18+AM18+BC18 -> 828000 | BV18: =+J18+Z18+AP18+BF18 -> 2268000 | BY18: =+M18+AC18+AS18+BI18 -> 8610000 | CB18: =SUM(BP18:BY18) -> 11706000
D20: 0 | G20: 0 | J20: 0 | M20: 0 | P20: =SUM(D20:M20) -> 0 | T20: 0 | W20: 0 | Z20: 0 | AC20: 0 | AF20: =SUM(T20:AC20) -> 0 | AJ20: 0 | AM20: 0 | AP20: 0 | AS20: 0 | AV20: =SUM(AJ20:AS20) -> 0 | AZ20: 0 | BC20: 0 | BF20: 0 | BI20: 0 | BL20: =SUM(AZ20:BI20) -> 0 | BP20: =+D20+T20+AJ20+AZ20 -> 0 | BS20: =+G20+W20+AM20+BC20 -> 0 | BV20: =+J20+Z20+AP20+BF20 -> 0 | BY20: =+M20+AC20+AS20+BI20 -> 0 | CB20: =SUM(BP20:BY20) -> 0
D22: 0 | G22: 0 | J22: 0 | M22: 0 | P22: =SUM(D22:M22) -> 0 | T22: 0 | W22: 0 | Z22: 0 | AC22: 0 | AF22: =SUM(T22:AC22) -> 0 | AJ22: 0 | AM22: 0 | AP22: 0 | AS22: 0 | AV22: =SUM(AJ22:AS22) -> 0 | AZ22: 0 | BC22: 0 | BF22: 0 | BI22: 0 | BL22: =SUM(AZ22:BI22) -> 0 | BP22: =+D22+T22+AJ22+AZ22 -> 0 | BS22: =+G22+W22+AM22+BC22 -> 0 | BV22: =+J22+Z22+AP22+BF22 -> 0 | BY22: =+M22+AC22+AS22+BI22 -> 0 | CB22: =SUM(BP22:BY22) -> 0
D24: 0 | G24: 0 | J24: 0 | M24: 0 | P24: =SUM(D24:M24) -> 0 | T24: 0 | W24: 0 | Z24: 0 | AC24: 0 | AF24: =SUM(T24:AC24) -> 0 | AJ24: 0 | AM24: 0 | AP24: 0 | AS24: 0 | AV24: =SUM(AJ24:AS24) -> 0 | AZ24: 0 | BC24: 0 | BF24: 0 | BI24: 0 | BL24: =SUM(AZ24:BI24) -> 0 | BP24: =+D24+T24+AJ24+AZ24 -> 0 | BS24: =+G24+W24+AM24+BC24 -> 0 | BV24: =+J24+Z24+AP24+BF24 -> 0 | BY24: =+M24+AC24+AS24+BI24 -> 0 | CB24: =SUM(BP24:BY24) -> 0
D26: 0 | G26: 0 | J26: 0 | M26: 0 | P26: =SUM(D26:M26) -> 0 | T26: 0 | W26: 0 | Z26: 0 | AC26: 0 | AF26: =SUM(T26:AC26) -> 0 | AJ26: 0 | AM26: 0 | AP26: 0 | AS26: 0 | AV26: =SUM(AJ26:AS26) -> 0 | AZ26: 0 | BC26: 0 | BF26: 0 | BI26: 0 | BL26: =SUM(AZ26:BI26) -> 0 | BP26: =+D26+T26+AJ26+AZ26 -> 0 | BS26: =+G26+W26+AM26+BC26 -> 0 | BV26: =+J26+Z26+AP26+BF26 -> 0 | BY26: =+M26+AC26+AS26+BI26 -> 0 | CB26: =SUM(BP26:BY26) -> 0
D28: 0 | G28: 0 | J28: 0 | M28: 0 | P28: =SUM(D28:M28) -> 0 | T28: 0 | W28: 0 | Z28: 0 | AC28: 0 | AF28: =SUM(T28:AC28) -> 0 | AJ28: 0 | AM28: 0 | AP28: 0 | AS28: 0 | AV28: =SUM(AJ28:AS28) -> 0 | AZ28: 0 | BC28: 0 | BF28: 0 | BI28: 0 | BL28: =SUM(AZ28:BI28) -> 0 | BP28: =+D28+T28+AJ28+AZ28 -> 0 | BS28: =+G28+W28+AM28+BC28 -> 0 | BV28: =+J28+Z28+AP28+BF28 -> 0 | BY28: =+M28+AC28+AS28+BI28 -> 0 | CB28: =SUM(BP28:BY28) -> 0
D30: 0 | G30: 0 | J30: 0 | M30: 0 | P30: =SUM(D30:M30) -> 0 | T30: 0 | W30: 0 | Z30: 0 | AC30: 0 | AF30: =SUM(T30:AC30) -> 0 | AJ30: 0 | AM30: 0 | AP30: 0 | AS30: 0 | AV30: =SUM(AJ30:AS30) -> 0 | AZ30: 0 | BC30: 0 | BF30: 0 | BI30: 0 | BL30: =SUM(AZ30:BI30) -> 0 | BP30: =+D30+T30+AJ30+AZ30 -> 0 | BS30: =+G30+W30+AM30+BC30 -> 0 | BV30: =+J30+Z30+AP30+BF30 -> 0 | BY30: =+M30+AC30+AS30+BI30 -> 0 | CB30: =SUM(BP30:BY30) -> 0
D32: 0 | G32: 0 | J32: 0 | M32: 0 | P32: =SUM(D32:M32) -> 0 | T32: 0 | W32: 0 | Z32: 0 | AC32: 0 | AF32: =SUM(T32:AC32) -> 0 | AJ32: 0 | AM32: 0 | AP32: 0 | AS32: 0 | AV32: =SUM(AJ32:AS32) -> 0 | AZ32: 0 | BC32: 0 | BF32: 0 | BI32: 0 | BL32: =SUM(AZ32:BI32) -> 0 | BP32: =+D32+T32+AJ32+AZ32 -> 0 | BS32: =+G32+W32+AM32+BC32 -> 0 | BV32: =+J32+Z32+AP32+BF32 -> 0 | BY32: =+M32+AC32+AS32+BI32 -> 0 | CB32: =SUM(BP32:BY32) -> 0
A35: Mejora Margen Comercial | D35: =SUM(D37:D56) -> 0 | G35: =SUM(G37:G56) -> 0 | J35: =SUM(J37:J56) -> 0 | M35: =SUM(M37:M56) -> 0 | P35: =SUM(P37:P56) -> 0 | T35: =SUM(T37:T56) -> 0 | W35: =SUM(W37:W56) -> 0 | Z35: =SUM(Z37:Z56) -> 0 | AC35: =SUM(AC37:AC56) -> 0 | AF35: =SUM(AF37:AF56) -> 0 | AJ35: =SUM(AJ37:AJ56) -> 0 | AM35: =SUM(AM37:AM56) -> 0 | AP35: =SUM(AP37:AP56) -> 0 | AS35: =SUM(AS37:AS56) -> 0 | AV35: =SUM(AV37:AV56) -> 0 | AZ35: =SUM(AZ37:AZ56) -> 0 | BC35: =SUM(BC37:BC56) -> 0 | BF35: =SUM(BF37:BF56) -> 0 | BI35: =SUM(BI37:BI56) -> 0 | BL35: =SUM(BL37:BL56) -> 0 | BP35: =SUM(BP37:BP56) -> 0 | BS35: =SUM(BS37:BS56) -> 0 | BV35: =SUM(BV37:BV56) -> 0 | BY35: =SUM(BY37:BY56) -> 0 | CB35: =SUM(CB37:CB56) -> 0
D37: 0 | G37: 0 | J37: 0 | M37: 0 | P37: =SUM(D37:M37) -> 0 | T37: 0 | W37: 0 | Z37: 0 | AC37: 0 | AF37: =SUM(T37:AC37) -> 0 | AJ37: 0 | AM37: 0 | AP37: 0 | AS37: 0 | AV37: =SUM(AJ37:AS37) -> 0 | AZ37: 0 | BC37: 0 | BF37: 0 | BI37: 0 | BL37: =SUM(AZ37:BI37) -> 0 | BP37: =+D37+T37+AJ37+AZ37 -> 0 | BS37: =+G37+W37+AM37+BC37 -> 0 | BV37: =+J37+Z37+AP37+BF37 -> 0 | BY37: =+M37+AC37+AS37+BI37 -> 0 | CB37: =SUM(BP37:BY37) -> 0
D39: 0 | G39: 0 | J39: 0 | M39: 0 | P39: =SUM(D39:M39) -> 0 | T39: 0 | W39: 0 | Z39: 0 | AC39: 0 | AF39: =SUM(T39:AC39) -> 0 | AJ39: 0 | AM39: 0 | AP39: 0 | AS39: 0 | AV39: =SUM(AJ39:AS39) -> 0 | AZ39: 0 | BC39: 0 | BF39: 0 | BI39: 0 | BL39: =SUM(AZ39:BI39) -> 0 | BP39: =+D39+T39+AJ39+AZ39 -> 0 | BS39: =+G39+W39+AM39+BC39 -> 0 | BV39: =+J39+Z39+AP39+BF39 -> 0 | BY39: =+M39+AC39+AS39+BI39 -> 0 | CB39: =SUM(BP39:BY39) -> 0
D41: 0 | G41: 0 | J41: 0 | M41: 0 | P41: =SUM(D41:M41) -> 0 | T41: 0 | W41: 0 | Z41: 0 | AC41: 0 | AF41: =SUM(T41:AC41) -> 0 | AJ41: 0 | AM41: 0 | AP41: 0 | AS41: 0 | AV41: =SUM(AJ41:AS41) -> 0 | AZ41: 0 | BC41: 0 | BF41: 0 | BI41: 0 | BL41: =SUM(AZ41:BI41) -> 0 | BP41: =+D41+T41+AJ41+AZ41 -> 0 | BS41: =+G41+W41+AM41+BC41 -> 0 | BV41: =+J41+Z41+AP41+BF41 -> 0 | BY41: =+M41+AC41+AS41+BI41 -> 0 | CB41: =SUM(BP41:BY41) -> 0
D43: 0 | G43: 0 | J43: 0 | M43: 0 | P43: =SUM(D43:M43) -> 0 | T43: 0 | W43: 0 | Z43: 0 | AC43: 0 | AF43: =SUM(T43:AC43) -> 0 | AJ43: 0 | AM43: 0 | AP43: 0 | AS43: 0 | AV43: =SUM(AJ43:AS43) -> 0 | AZ43: 0 | BC43: 0 | BF43: 0 | BI43: 0 | BL43: =SUM(AZ43:BI43) -> 0 | BP43: =+D43+T43+AJ43+AZ43 -> 0 | BS43: =+G43+W43+AM43+BC43 -> 0 | BV43: =+J43+Z43+AP43+BF43 -> 0 | BY43: =+M43+AC43+AS43+BI43 -> 0 | CB43: =SUM(BP43:BY43) -> 0
D45: 0 | G45: 0 | J45: 0 | M45: 0 | P45: =SUM(D45:M45) -> 0 | T45: 0 | W45: 0 | Z45: 0 | AC45: 0 | AF45: =SUM(T45:AC45) -> 0 | AJ45: 0 | AM45: 0 | AP45: 0 | AS45: 0 | AV45: =SUM(AJ45:AS45) -> 0 | AZ45: 0 | BC45: 0 | BF45: 0 | BI45: 0 | BL45: =SUM(AZ45:BI45) -> 0 | BP45: =+D45+T45+AJ45+AZ45 -> 0 | BS45: =+G45+W45+AM45+BC45 -> 0 | BV45: =+J45+Z45+AP45+BF45 -> 0 | BY45: =+M45+AC45+AS45+BI45 -> 0 | CB45: =SUM(BP45:BY45) -> 0
D47: 0 | G47: 0 | J47: 0 | M47: 0 | P47: =SUM(D47:M47) -> 0 | T47: 0 | W47: 0 | Z47: 0 | AC47: 0 | AF47: =SUM(T47:AC47) -> 0 | AJ47: 0 | AM47: 0 | AP47: 0 | AS47: 0 | AV47: =SUM(AJ47:AS47) -> 0 | AZ47: 0 | BC47: 0 | BF47: 0 | BI47: 0 | BL47: =SUM(AZ47:BI47) -> 0 | BP47: =+D47+T47+AJ47+AZ47 -> 0 | BS47: =+G47+W47+AM47+BC47 -> 0 | BV47: =+J47+Z47+AP47+BF47 -> 0 | BY47: =+M47+AC47+AS47+BI47 -> 0 | CB47: =SUM(BP47:BY47) -> 0
D49: 0 | G49: 0 | J49: 0 | M49: 0 | P49: =SUM(D49:M49) -> 0 | T49: 0 | W49: 0 | Z49: 0 | AC49: 0 | AF49: =SUM(T49:AC49) -> 0 | AJ49: 0 | AM49: 0 | AP49: 0 | AS49: 0 | AV49: =SUM(AJ49:AS49) -> 0 | AZ49: 0 | BC49: 0 | BF49: 0 | BI49: 0 | BL49: =SUM(AZ49:BI49) -> 0 | BP49: =+D49+T49+AJ49+AZ49 -> 0 | BS49: =+G49+W49+AM49+BC49 -> 0 | BV49: =+J49+Z49+AP49+BF49 -> 0 | BY49: =+M49+AC49+AS49+BI49 -> 0 | CB49: =SUM(BP49:BY49) -> 0
D51: 0 | G51: 0 | J51: 0 | M51: 0 | P51: =SUM(D51:M51) -> 0 | T51: 0 | W51: 0 | Z51: 0 | AC51: 0 | AF51: =SUM(T51:AC51) -> 0 | AJ51: 0 | AM51: 0 | AP51: 0 | AS51: 0 | AV51: =SUM(AJ51:AS51) -> 0 | AZ51: 0 | BC51: 0 | BF51: 0 | BI51: 0 | BL51: =SUM(AZ51:BI51) -> 0 | BP51: =+D51+T51+AJ51+AZ51 -> 0 | BS51: =+G51+W51+AM51+BC51 -> 0 | BV51: =+J51+Z51+AP51+BF51 -> 0 | BY51: =+M51+AC51+AS51+BI51 -> 0 | CB51: =SUM(BP51:BY51) -> 0
D53: 0 | G53: 0 | J53: 0 | M53: 0 | P53: =SUM(D53:M53) -> 0 | T53: 0 | W53: 0 | Z53: 0 | AC53: 0 | AF53: =SUM(T53:AC53) -> 0 | AJ53: 0 | AM53: 0 | AP53: 0 | AS53: 0 | AV53: =SUM(AJ53:AS53) -> 0 | AZ53: 0 | BC53: 0 | BF53: 0 | BI53: 0 | BL53: =SUM(AZ53:BI53) -> 0 | BP53: =+D53+T53+AJ53+AZ53 -> 0 | BS53: =+G53+W53+AM53+BC53 -> 0 | BV53: =+J53+Z53+AP53+BF53 -> 0 | BY53: =+M53+AC53+AS53+BI53 -> 0 | CB53: =SUM(BP53:BY53) -> 0
D55: 0 | G55: 0 | J55: 0 | M55: 0 | P55: =SUM(D55:M55) -> 0 | T55: 0 | W55: 0 | Z55: 0 | AC55: 0 | AF55: =SUM(T55:AC55) -> 0 | AJ55: 0 | AM55: 0 | AP55: 0 | AS55: 0 | AV55: =SUM(AJ55:AS55) -> 0 | AZ55: 0 | BC55: 0 | BF55: 0 | BI55: 0 | BL55: =SUM(AZ55:BI55) -> 0 | BP55: =+D55+T55+AJ55+AZ55 -> 0 | BS55: =+G55+W55+AM55+BC55 -> 0 | BV55: =+J55+Z55+AP55+BF55 -> 0 | BY55: =+M55+AC55+AS55+BI55 -> 0 | CB55: =SUM(BP55:BY55) -> 0
A58: Nuevos Productos / Mercados | D58: =SUM(D60:D79) -> 0 | G58: =SUM(G60:G79) -> 0 | J58: =SUM(J60:J79) -> 100000 | M58: =SUM(M60:M79) -> 150000 | P58: =SUM(P60:P79) -> 250000 | T58: =SUM(T60:T79) -> 0 | W58: =SUM(W60:W79) -> 0 | Z58: =SUM(Z60:Z79) -> 0 | AC58: =SUM(AC60:AC79) -> 0 | AF58: =SUM(AF60:AF79) -> 0 | AJ58: =SUM(AJ60:AJ79) -> 0 | AM58: =SUM(AM60:AM79) -> 0 | AP58: =SUM(AP60:AP79) -> 0 | AS58: =SUM(AS60:AS79) -> 0 | AV58: =SUM(AV60:AV79) -> 0 | AZ58: =SUM(AZ60:AZ79) -> 0 | BC58: =SUM(BC60:BC79) -> 0 | BF58: =SUM(BF60:BF79) -> 0 | BI58: =SUM(BI60:BI79) -> 0 | BL58: =SUM(BL60:BL79) -> 0 | BP58: =SUM(BP60:BP79) -> 0 | BS58: =SUM(BS60:BS79) -> 0 | BV58: =SUM(BV60:BV79) -> 100000 | BY58: =SUM(BY60:BY79) -> 150000 | CB58: =SUM(CB60:CB79) -> 250000
A60: VENTA BASES DE DATOS | J60: 75000 | M60: 100000 | P60: =SUM(D60:M60) -> 175000 | T60: 0 | W60: 0 | Z60: 0 | AC60: 0 | AF60: =SUM(T60:AC60) -> 0 | AJ60: 0 | AM60: 0 | AP60: 0 | AS60: 0 | AV60: =SUM(AJ60:AS60) -> 0 | AZ60: 0 | BC60: 0 | BF60: 0 | BI60: 0 | BL60: =SUM(AZ60:BI60) -> 0 | BP60: =+D60+T60+AJ60+AZ60 -> 0 | BS60: =+G60+W60+AM60+BC60 -> 0 | BV60: =+J60+Z60+AP60+BF60 -> 75000 | BY60: =+M60+AC60+AS60+BI60 -> 100000 | CB60: =SUM(BP60:BY60) -> 175000
A62: INFORMES DE MERCADO | D62: 0 | G62: 0 | J62: 25000 | M62: 50000 | P62: =SUM(D62:M62) -> 75000 | T62: 0 | W62: 0 | Z62: 0 | AC62: 0 | AF62: =SUM(T62:AC62) -> 0 | AJ62: 0 | AM62: 0 | AP62: 0 | AS62: 0 | AV62: =SUM(AJ62:AS62) -> 0 | AZ62: 0 | BC62: 0 | BF62: 0 | BI62: 0 | BL62: =SUM(AZ62:BI62) -> 0 | BP62: =+D62+T62+AJ62+AZ62 -> 0 | BS62: =+G62+W62+AM62+BC62 -> 0 | BV62: =+J62+Z62+AP62+BF62 -> 25000 | BY62: =+M62+AC62+AS62+BI62 -> 50000 | CB62: =SUM(BP62:BY62) -> 75000
D64: 0 | G64: 0 | J64: 0 | M64: 0 | P64: =SUM(D64:M64) -> 0 | T64: 0 | W64: 0 | Z64: 0 | AC64: 0 | AF64: =SUM(T64:AC64) -> 0 | AJ64: 0 | AM64: 0 | AP64: 0 | AS64: 0 | AV64: =SUM(AJ64:AS64) -> 0 | AZ64: 0 | BC64: 0 | BF64: 0 | BI64: 0 | BL64: =SUM(AZ64:BI64) -> 0 | BP64: =+D64+T64+AJ64+AZ64 -> 0 | BS64: =+G64+W64+AM64+BC64 -> 0 | BV64: =+J64+Z64+AP64+BF64 -> 0 | BY64: =+M64+AC64+AS64+BI64 -> 0 | CB64: =SUM(BP64:BY64) -> 0
D66: 0 | G66: 0 | J66: 0 | M66: 0 | P66: =SUM(D66:M66) -> 0 | T66: 0 | W66: 0 | Z66: 0 | AC66: 0 | AF66: =SUM(T66:AC66) -> 0 | AJ66: 0 | AM66: 0 | AP66: 0 | AS66: 0 | AV66: =SUM(AJ66:AS66) -> 0 | AZ66: 0 | BC66: 0 | BF66: 0 | BI66: 0 | BL66: =SUM(AZ66:BI66) -> 0 | BP66: =+D66+T66+AJ66+AZ66 -> 0 | BS66: =+G66+W66+AM66+BC66 -> 0 | BV66: =+J66+Z66+AP66+BF66 -> 0 | BY66: =+M66+AC66+AS66+BI66 -> 0 | CB66: =SUM(BP66:BY66) -> 0
D68: 0 | G68: 0 | J68: 0 | M68: 0 | P68: =SUM(D68:M68) -> 0 | T68: 0 | W68: 0 | Z68: 0 | AC68: 0 | AF68: =SUM(T68:AC68) -> 0 | AJ68: 0 | AM68: 0 | AP68: 0 | AS68: 0 | AV68: =SUM(AJ68:AS68) -> 0 | AZ68: 0 | BC68: 0 | BF68: 0 | BI68: 0 | BL68: =SUM(AZ68:BI68) -> 0 | BP68: =+D68+T68+AJ68+AZ68 -> 0 | BS68: =+G68+W68+AM68+BC68 -> 0 | BV68: =+J68+Z68+AP68+BF68 -> 0 | BY68: =+M68+AC68+AS68+BI68 -> 0 | CB68: =SUM(BP68:BY68) -> 0
D70: 0 | G70: 0 | J70: 0 | M70: 0 | P70: =SUM(D70:M70) -> 0 | T70: 0 | W70: 0 | Z70: 0 | AC70: 0 | AF70: =SUM(T70:AC70) -> 0 | AJ70: 0 | AM70: 0 | AP70: 0 | AS70: 0 | AV70: =SUM(AJ70:AS70) -> 0 | AZ70: 0 | BC70: 0 | BF70: 0 | BI70: 0 | BL70: =SUM(AZ70:BI70) -> 0 | BP70: =+D70+T70+AJ70+AZ70 -> 0 | BS70: =+G70+W70+AM70+BC70 -> 0 | BV70: =+J70+Z70+AP70+BF70 -> 0 | BY70: =+M70+AC70+AS70+BI70 -> 0 | CB70: =SUM(BP70:BY70) -> 0
D72: 0 | G72: 0 | J72: 0 | M72: 0 | P72: =SUM(D72:M72) -> 0 | T72: 0 | W72: 0 | Z72: 0 | AC72: 0 | AF72: =SUM(T72:AC72) -> 0 | AJ72: 0 | AM72: 0 | AP72: 0 | AS72: 0 | AV72: =SUM(AJ72:AS72) -> 0 | AZ72: 0 | BC72: 0 | BF72: 0 | BI72: 0 | BL72: =SUM(AZ72:BI72) -> 0 | BP72: =+D72+T72+AJ72+AZ72 -> 0 | BS72: =+G72+W72+AM72+BC72 -> 0 | BV72: =+J72+Z72+AP72+BF72 -> 0 | BY72: =+M72+AC72+AS72+BI72 -> 0 | CB72: =SUM(BP72:BY72) -> 0
D74: 0 | G74: 0 | J74: 0 | M74: 0 | P74: =SUM(D74:M74) -> 0 | T74: 0 | W74: 0 | Z74: 0 | AC74: 0 | AF74: =SUM(T74:AC74) -> 0 | AJ74: 0 | AM74: 0 | AP74: 0 | AS74: 0 | AV74: =SUM(AJ74:AS74) -> 0 | AZ74: 0 | BC74: 0 | BF74: 0 | BI74: 0 | BL74: =SUM(AZ74:BI74) -> 0 | BP74: =+D74+T74+AJ74+AZ74 -> 0 | BS74: =+G74+W74+AM74+BC74 -> 0 | BV74: =+J74+Z74+AP74+BF74 -> 0 | BY74: =+M74+AC74+AS74+BI74 -> 0 | CB74: =SUM(BP74:BY74) -> 0
D76: 0 | G76: 0 | J76: 0 | M76: 0 | P76: =SUM(D76:M76) -> 0 | T76: 0 | W76: 0 | Z76: 0 | AC76: 0 | AF76: =SUM(T76:AC76) -> 0 | AJ76: 0 | AM76: 0 | AP76: 0 | AS76: 0 | AV76: =SUM(AJ76:AS76) -> 0 | AZ76: 0 | BC76: 0 | BF76: 0 | BI76: 0 | BL76: =SUM(AZ76:BI76) -> 0 | BP76: =+D76+T76+AJ76+AZ76 -> 0 | BS76: =+G76+W76+AM76+BC76 -> 0 | BV76: =+J76+Z76+AP76+BF76 -> 0 | BY76: =+M76+AC76+AS76+BI76 -> 0 | CB76: =SUM(BP76:BY76) -> 0
D78: 0 | G78: 0 | J78: 0 | M78: 0 | P78: =SUM(D78:M78) -> 0 | T78: 0 | W78: 0 | Z78: 0 | AC78: 0 | AF78: =SUM(T78:AC78) -> 0 | AJ78: 0 | AM78: 0 | AP78: 0 | AS78: 0 | AV78: =SUM(AJ78:AS78) -> 0 | AZ78: 0 | BC78: 0 | BF78: 0 | BI78: 0 | BL78: =SUM(AZ78:BI78) -> 0 | BP78: =+D78+T78+AJ78+AZ78 -> 0 | BS78: =+G78+W78+AM78+BC78 -> 0 | BV78: =+J78+Z78+AP78+BF78 -> 0 | BY78: =+M78+AC78+AS78+BI78 -> 0 | CB78: =SUM(BP78:BY78) -> 0

Sheet Riesgos
B2: EVALUACIÓN DE RIESGOS | G2: Valores | J2: Corrección | K2: DÑ
G3: Probabilidad | I3: Impacto | J3: Inversión | K3: Ingresos / Costes
G5: 1 | I5: Muy Alto | J5: 0.25 | K5: 0.1
G6: 0.8 | I6: Alto | J6: 0.2 | K6: 0.08
G7: 0.6 | I7: Medio | J7: 0.15 | K7: 0.06
G8: 0.4 | I8: Bajo | J8: 0.1 | K8: 0.04
G9: 0.2 | I9: Muy Bajo | J9: 0.05 | K9: 0.02
G10: 0 | I10: --- | J10: 0 | K10: 0
A12: Proyecto: | C12: =+Definición!C2 -> TRIPMATE
A14: Subproyecto 1 | C14: =+Definición!C4 -> TRIPMATE
B16: Tipo de riesgo | C16: Probabilidad | E16: Impacto | I16: Coeficiente de corrección
E17: Inversión | F17: D Ingresos | G17: Ñ Costes | I17: Inversión | J17: D Ingresos | K17: Ñ Costes
A18: R1 | B18: NO ALCANZAR TARGET USUARIO | C18: 0.2 | E18: Bajo | F18: Alto | G18: Medio | I18: =0+(VLOOKUP(E18,$I$5:$K$10,2,FALSE))*C18 -> 0.02 | J18: =VLOOKUP(F18,$I$5:$K$10,3,FALSE)*$C18 -> 0.016 | K18: =VLOOKUP(G18,$I$5:$K$10,3,FALSE)*$C18 -> 0.012
A19: R2 | E19: --- | F19: --- | G19: --- | I19: =0+(VLOOKUP(E19,$I$5:$K$10,2,FALSE))*C19 -> 0 | J19: =VLOOKUP(F19,$I$5:$K$10,3,FALSE)*$C19 -> 0 | K19: =VLOOKUP(G19,$I$5:$K$10,3,FALSE)*$C19 -> 0
A20: R3 | E20: --- | F20: --- | G20: --- | I20: =0+(VLOOKUP(E20,$I$5:$K$10,2,FALSE))*C20 -> 0 | J20: =VLOOKUP(F20,$I$5:$K$10,3,FALSE)*$C20 -> 0 | K20: =VLOOKUP(G20,$I$5:$K$10,3,FALSE)*$C20 -> 0
A21: R4 | E21: --- | F21: --- | G21: --- | I21: =0+(VLOOKUP(E21,$I$5:$K$10,2,FALSE))*C21 -> 0 | J21: =VLOOKUP(F21,$I$5:$K$10,3,FALSE)*$C21 -> 0 | K21: =VLOOKUP(G21,$I$5:$K$10,3,FALSE)*$C21 -> 0
A22: R5 | E22: --- | F22: --- | G22: --- | I22: =0+(VLOOKUP(E22,$I$5:$K$10,2,FALSE))*C22 -> 0 | J22: =VLOOKUP(F22,$I$5:$K$10,3,FALSE)*$C22 -> 0 | K22: =VLOOKUP(G22,$I$5:$K$10,3,FALSE)*$C22 -> 0
A23: R6 | E23: --- | F23: --- | G23: --- | I23: =0+(VLOOKUP(E23,$I$5:$K$10,2,FALSE))*C23 -> 0 | J23: =VLOOKUP(F23,$I$5:$K$10,3,FALSE)*$C23 -> 0 | K23: =VLOOKUP(G23,$I$5:$K$10,3,FALSE)*$C23 -> 0
A24: R7 | E24: --- | F24: --- | G24: --- | I24: =0+(VLOOKUP(E24,$I$5:$K$10,2,FALSE))*C24 -> 0 | J24: =VLOOKUP(F24,$I$5:$K$10,3,FALSE)*$C24 -> 0 | K24: =VLOOKUP(G24,$I$5:$K$10,3,FALSE)*$C24 -> 0
A25: R8 | E25: --- | F25: --- | G25: --- | I25: =0+(VLOOKUP(E25,$I$5:$K$10,2,FALSE))*C25 -> 0 | J25: =VLOOKUP(F25,$I$5:$K$10,3,FALSE)*$C25 -> 0 | K25: =VLOOKUP(G25,$I$5:$K$10,3,FALSE)*$C25 -> 0
A26: R9 | E26: --- | F26: --- | G26: --- | I26: =0+(VLOOKUP(E26,$I$5:$K$10,2,FALSE))*C26 -> 0 | J26: =VLOOKUP(F26,$I$5:$K$10,3,FALSE)*$C26 -> 0 | K26: =VLOOKUP(G26,$I$5:$K$10,3,FALSE)*$C26 -> 0
A27: R10 | E27: --- | F27: --- | G27: --- | I27: =0+(VLOOKUP(E27,$I$5:$K$10,2,FALSE))*C27 -> 0 | J27: =VLOOKUP(F27,$I$5:$K$10,3,FALSE)*$C27 -> 0 | K27: =VLOOKUP(G27,$I$5:$K$10,3,FALSE)*$C27 -> 0
B29: Número de riesgos cualificados | C29: =COUNT(C18:C27) -> 1 | I29: =SUM(I18:I28)+1 -> 1.02 | J29: =1-SUM(J18:J28) -> 0.984 | K29: =1-SUM(K18:K28) -> 0.988
A32: Subproyecto 2 | C32: =+Definición!C11 -> [Nombre ]
B34: Tipo de riesgo | C34: Probabilidad | E34: Impacto | I34: Coeficiente de corrección
E35: Inversión | F35: D Ingresos | G35: Ñ Costes | I35: Inversión | J35: D Ingresos | K35: Ñ Costes
A36: R1 | B36: Riesgo 1 | C36: 0 | E36: --- | F36: --- | G36: --- | I36: =0+(VLOOKUP(E36,$I$5:$K$10,2,FALSE))*C36 -> 0 | J36: =VLOOKUP(F36,$I$5:$K$10,3,FALSE)*$C36 -> 0 | K36: =VLOOKUP(G36,$I$5:$K$10,3,FALSE)*$C36 -> 0
A37: R2 | E37: --- | F37: --- | G37: --- | I37: =0+(VLOOKUP(E37,$I$5:$K$10,2,FALSE))*C37 -> 0 | J37: =VLOOKUP(F37,$I$5:$K$10,3,FALSE)*$C37 -> 0 | K37: =VLOOKUP(G37,$I$5:$K$10,3,FALSE)*$C37 -> 0
A38: R3 | E38: --- | F38: --- | G38: --- | I38: =0+(VLOOKUP(E38,$I$5:$K$10,2,FALSE))*C38 -> 0 | J38: =VLOOKUP(F38,$I$5:$K$10,3,FALSE)*$C38 -> 0 | K38: =VLOOKUP(G38,$I$5:$K$10,3,FALSE)*$C38 -> 0
A39: R4 | E39: --- | F39: --- | G39: --- | I39: =0+(VLOOKUP(E39,$I$5:$K$10,2,FALSE))*C39 -> 0 | J39: =VLOOKUP(F39,$I$5:$K$10,3,FALSE)*$C39 -> 0 | K39: =VLOOKUP(G39,$I$5:$K$10,3,FALSE)*$C39 -> 0
A40: R5 | E40: --- | F40: --- | G40: --- | I40: =0+(VLOOKUP(E40,$I$5:$K$10,2,FALSE))*C40 -> 0 | J40: =VLOOKUP(F40,$I$5:$K$10,3,FALSE)*$C40 -> 0 | K40: =VLOOKUP(G40,$I$5:$K$10,3,FALSE)*$C40 -> 0
A41: R6 | E41: --- | F41: --- | G41: --- | I41: =0+(VLOOKUP(E41,$I$5:$K$10,2,FALSE))*C41 -> 0 | J41: =VLOOKUP(F41,$I$5:$K$10,3,FALSE)*$C41 -> 0 | K41: =VLOOKUP(G41,$I$5:$K$10,3,FALSE)*$C41 -> 0
A42: R7 | E42: --- | F42: --- | G42: --- | I42: =0+(VLOOKUP(E42,$I$5:$K$10,2,FALSE))*C42 -> 0 | J42: =VLOOKUP(F42,$I$5:$K$10,3,FALSE)*$C42 -> 0 | K42: =VLOOKUP(G42,$I$5:$K$10,3,FALSE)*$C42 -> 0
A43: R8 | E43: --- | F43: --- | G43: --- | I43: =0+(VLOOKUP(E43,$I$5:$K$10,2,FALSE))*C43 -> 0 | J43: =VLOOKUP(F43,$I$5:$K$10,3,FALSE)*$C43 -> 0 | K43: =VLOOKUP(G43,$I$5:$K$10,3,FALSE)*$C43 -> 0
A44: R9 | E44: --- | F44: --- | G44: --- | I44: =0+(VLOOKUP(E44,$I$5:$K$10,2,FALSE))*C44 -> 0 | J44: =VLOOKUP(F44,$I$5:$K$10,3,FALSE)*$C44 -> 0 | K44: =VLOOKUP(G44,$I$5:$K$10,3,FALSE)*$C44 -> 0
A45: R10 | E45: --- | F45: --- | G45: --- | I45: =0+(VLOOKUP(E45,$I$5:$K$10,2,FALSE))*C45 -> 0 | J45: =VLOOKUP(F45,$I$5:$K$10,3,FALSE)*$C45 -> 0 | K45: =VLOOKUP(G45,$I$5:$K$10,3,FALSE)*$C45 -> 0
B47: Número de riesgos cualificados | C47: =COUNT(C36:C45) -> 1 | I47: =SUM(I36:I46)+1 -> 1 | J47: =1-SUM(J36:J46) -> 1 | K47: =1-SUM(K36:K46) -> 1
A50: Subproyecto 3 | C50: =+Definición!C18 -> [Nombre ]
B52: Tipo de riesgo | C52: Probabilidad | E52: Impacto | I52: Coeficiente de corrección
E53: Inversión | F53: D Ingresos | G53: Ñ Costes | I53: Inversión | J53: D Ingresos | K53: Ñ Costes
...

Sheet ROI
B2: RETORNO DE LA INVERSION (GLOBAL) - ROI -
C7: Proyecto: | D7: =+Definición!C2 -> TRIPMATE
C9: Global Proyecto
E11: Cálculo Base | H11: Ajustado al Riesgo | K11: Año1 | L11: Año2 | M11: Año3 | N11: Año4
P12: Valor Residual
C13: Inversión | E13: =+E31+E48+E65+E82 -> 2288000 | H13: =+H31+H48+H65+H82 -> 2333760 | K13: =+K31+K48+K65+K82 -> 1593000 | L13: =+L31+L48+L65+L82 -> 227000 | M13: =+M31+M48+M65+M82 -> 311000 | N13: =+N31+N48+N65+N82 -> 157000 | P13: =+P31+P48+P65+P82 -> 0
C15: D Ingresos | E15: =+E33+E50+E67+E84 -> 18547150 | H15: =+H33+H50+H67+H84 -> 18250396 | K15: =+K33+K50+K67+K84 -> 0 | L15: =+L33+L50+L67+L84 -> 1706580 | M15: =+M33+M50+M67+M84 -> 4418020 | N15: =+N33+N50+N67+N84 -> 12422550
C17: Ñ Costes | E17: =+E35+E52+E69+E86 -> 13126000 | H17: =+H35+H52+H69+H86 -> 12968488 | K17: =+K35+K52+K69+K86 -> 449000 | L17: =+L35+L52+L69+L86 -> 2469000 | M17: =+M35+M52+M69+M86 -> 3119000 | N17: =+N35+N52+N69+N86 -> 7089000
